Workbook
Name FIXTURE_IDS: OFFSET(DAFTAR_FIXTURE!$A$2,0,0,MAX(1,COUNTA(DAFTAR_FIXTURE!$A$2:$A$51)),1)

Sheet PETUNJUK
A1: TEMPLATE DATA PLANOGRAM
A2: Isi sheet DATA dari kiri ke kanan. Satu baris = satu SKU. Kolom A–K = template wajib internal. Kolom L ke kanan = penempatan fixture khusus untuk HTML planogram.
A4: LANGKAH 1 — TEMPLATE WAJIB INTERNAL (kolom A–K)
A5: DEPT, COMM, CLASS | B5: Hirarki produk dari data master. Dipakai sebagai filter di aplikasi.
A6: SKU * | B6: Kode artikel. Wajib. Dipakai juga untuk membentuk link gambar.
A7: SKU DESCRIPTION * | B7: Nama item. Wajib. Tampil di kartu produk.
A8: STOCK | B8: Informasi stok SKU (dari data master).
A9: GRUP DISPLAY | B9: Contoh: PENYIMPANAN, MAKAN, MASAK. Dipakai sebagai filter. Isi "X" dianggap kosong.
A10: GRUP ADJACENCY | B10: Contoh: E4. CANISTER, A2. SERVINGWARE. Dipakai sebagai filter.
A11: SERIES / SUB SERIES | B11: Contoh: GLASS FANCY, POLLA. Dipakai sebagai filter.
A12: LINK IMAGE | B12: Opsional. Kosong = otomatis: https://cdn.ruparupa.io/fit-in/850x850/ruparupa-com/image/upload/Products/[SKU]_1.jpg
A14: LANGKAH 2 — PENEMPATAN KE FIXTURE, SAMPAI 3 FIXTURE PER SKU (header hijau)
A15: FIXTURE 1 (kolom L–N) | B15: ID FIXTURE 1 (dropdown dari sheet DAFTAR_FIXTURE), ZONA NO 1 (dari atas, mulai 1; lihat sheet LAYOUT), JENIS ZONA 1 (Rak / Gantungan).
A16: FIXTURE 2 (kolom Q–S) | B16: Isi jika SKU yang sama juga ditampilkan di fixture lain (mis. Wall dan Gondola). Kosongkan jika tidak dipakai.
A17: FIXTURE 3 (kolom V–X) | B17: Cadangan untuk fixture ketiga. Kosongkan jika tidak dipakai.
A19: LANGKAH 3 — OTOMATIS (header abu-abu, jangan diisi / dihapus)
A20: JENIS FIXTURE 1 / 2 / 3 | B20: Dibaca dari ID FIXTURE (sheet DAFTAR_FIXTURE).
A21: STATUS 1 / 2 / 3 | B21: OK / Zona STOCK / Belum ditempatkan / CEK + penyebab. Semua penempatan harus OK sebelum diimpor.
A23: ATURAN PENEMPATAN
A24: 1. Satu baris = satu SKU. SKU yang sama tidak perlu ditulis lagi untuk fixture kedua / ketiga: isi kolom Fixture 2 / Fixture 3 pada baris yang sama.
A25: 2. Jika satu SKU perlu lebih dari 3 penempatan (mis. di banyak zona), tulis SKU itu lagi di baris baru.
A26: 3. Urutan item dari kiri ke kanan dalam satu zona mengikuti urutan baris di Excel (baris atas lebih dulu).
A27: 4. Jumlah item yang tampil = jumlah penempatan. Tidak ada facing, susun, ukuran, brand, atau prioritas.
A28: 5. Zona yang tidak berisi item (baris ID FIXTURE 1 + ZONA NO 1 tanpa SKU, atau zona yang tidak ditulis sama sekali) dianggap tempat STOCK dan ditulis STOCK di planogram.
A29: 6. Baris yang hanya berisi data SKU (tanpa ID FIXTURE) = masuk daftar SKU saja, belum ditempatkan.
A30: 7. Isi GRUP DISPLAY, GRUP ADJACENCY, SERIES dengan ejaan konsisten agar pilihan filter di aplikasi tidak terpecah.
A31: Buka dulu di Excel lalu simpan agar kolom otomatis terhitung sebelum diimpor.
A33: SHEET DIMENSI (OPSIONAL) — ukuran kemasan untuk menghitung muat berapa pcs
A34: Kapan dipakai | B34: Hanya jika sheet DIMENSI berisi data DAN pengguna meminta di aplikasi. Kosong = aplikasi berjalan seperti biasa.
A35: SKU * | B35: Harus sama dengan kolom SKU di sheet DATA. Satu SKU satu baris.
A36: LEBAR / TINGGI / KEDALAMAN (cm) * | B36: Ukuran kemasan saat dipajang. LEBAR = sisi yang menghadap depan (kiri-kanan); TINGGI = atas-bawah; KEDALAMAN = depan-belakang. Untuk kemasan gantung, kedalaman = tebal kemasan.
A37: FACING | B37: Jumlah deretan produk berdampingan di depan. Kosong = 1.
A38: MAKS SUSUN | B38: Boleh ditumpuk berapa tingkat. Kosong atau 1 = tidak ditumpuk.
A39: BOLEH DIPUTAR | B39: Ya = lebar dan kedalaman boleh ditukar bila itu membuat lebih banyak yang muat. Kosong = Tidak.
A40: Kolom otomatis | B40: Deskripsi, estimasi pcs per facing (gambaran cepat rak Gondola), dan STATUS. Jangan diisi atau dihapus.
A42: SHEET SAMBUNG (OPSIONAL) — template urutan fixture yang disambung, per kategori
A43: Fungsi | B43: Menyimpan urutan fixture yang tampil menempel (Sambung visual) di aplikasi. Muncul sebagai pilihan "Template sambungan dari Excel". Kosong = tidak ada template.
A44: SAMBUNGAN * | B44: Nama rangkaian, bebas (mis. WALL-RUN-1). Baris dengan nama sama = satu rangkaian.
A45: KATEGORI * | B45: Wall, Gondola, atau Pallet. Satu rangkaian satu kategori. Endcap tidak ikut sambung.
A46: URUTAN * | B46: Nomor urut dari kiri ke kanan, mulai 1.
...

Sheet DATA
A1: DEPT | B1: COMM | C1: CLASS | D1: SKU | E1: SKU DESCRIPTION | F1: STOCK | G1: GRUP DISPLAY | H1: GRUP ADJACENCY | I1: SERIES | J1: SUB SERIES* | K1: LINK IMAGE (opsional) | L1: ID FIXTURE 1 | M1: ZONA NO 1 | N1: JENIS ZONA 1 | O1: JENIS FIXTURE 1 (otomatis) | P1: STATUS 1 (otomatis) | Q1: ID FIXTURE 2 | R1: ZONA NO 2 | S1: JENIS ZONA 2 | T1: JENIS FIXTURE 2 (otomatis) | U1: STATUS 2 (otomatis) | V1: ID FIXTURE 3 | W1: ZONA NO 3 | X1: JENIS ZONA 3 | Y1: JENIS FIXTURE 3 (otomatis) | Z1: STATUS 3 (otomatis)
A2: Homeware | B2: Tableware | C2: Plates & Bowls | D2: 238181 | E2: COUPE PLATE 16 CM SIMPLE PLUS | L2: WLL-01 | M2: 1 | N2: Rak | O2: =IF(L2="","",IFERROR(INDEX(DAFTAR_FIXTURE!$B$2:$B$51,MATCH(L2,DAFTAR_FIXTURE!$A$2:$A$51,0)),"")) | P2: =IF(AND($D2="",L2=""),"",IF(L2="",IF(AND(Q2="",V2=""),"Belum ditempatkan",""),IF(O2="","CEK ID FIXTURE tidak ada di DAFTAR_FIXTURE",IF(M2="","CEK ZONA NO kosong",IF(ISNA(MATCH(O2&"|"&M2,LAYOUT!$E$2:$E$80,0)),"CEK ZONA NO di luar layout",IF(N2<>INDEX(LAYOUT!$D$2:$D$80,MATCH(O2&"|"&M2,LAYOUT!$E$2:$E$80,0)),"CEK JENIS ZONA",IF($D2="","Zona STOCK",IF($E2="","CEK SKU DESCRIPTION kosong","OK")))))))) | T2: =IF(Q2="","",IFERROR(INDEX(DAFTAR_FIXTURE!$B$2:$B$51,MATCH(Q2,DAFTAR_FIXTURE!$A$2:$A$51,0)),"")) | U2: =IF(Q2="","",IF(T2="","CEK ID FIXTURE tidak ada di DAFTAR_FIXTURE",IF(R2="","CEK ZONA NO kosong",IF(ISNA(MATCH(T2&"|"&R2,LAYOUT!$E$2:$E$80,0)),"CEK ZONA NO di luar layout",IF(S2<>INDEX(LAYOUT!$D$2:$D$80,MATCH(T2&"|"&R2,LAYOUT!$E$2:$E$80,0)),"CEK JENIS ZONA",IF($D2="","Zona STOCK",IF($E2="","CEK SKU DESCRIPTION kosong","OK"))))))) | Y2: =IF(V2="","",IFERROR(INDEX(DAFTAR_FIXTURE!$B$2:$B$51,MATCH(V2,DAFTAR_FIXTURE!$A$2:$A$51,0)),"")) | Z2: =IF(V2="","",IF(Y2="","CEK ID FIXTURE tidak ada di DAFTAR_FIXTURE",IF(W2="","CEK ZONA NO kosong",IF(ISNA(MATCH(Y2&"|"&W2,LAYOUT!$E$2:$E$80,0)),"CEK ZONA NO di luar layout",IF(X2<>INDEX(LAYOUT!$D$2:$D$80,MATCH(Y2&"|"&W2,LAYOUT!$E$2:$E$80,0)),"CEK JENIS ZONA",IF($D2="","Zona STOCK",IF($E2="","CEK SKU DESCRIPTION kosong","OK")))))))
A3: Homeware | B3: Cookware | C3: Casserole | D3: 10445959 | E3: CASSEROLE RECT GOLD MARBLE W/LID 33CM | G3: MASAK | H3: B1. CASSEROLE | I3: GOLD MARBLE | L3: WLL-01 | M3: 2 | N3: Rak | O3: =IF(L3="","",IFERROR(INDEX(DAFTAR_FIXTURE!$B$2:$B$51,MATCH(L3,DAFTAR_FIXTURE!$A$2:$A$51,0)),"")) | P3: =IF(AND($D3="",L3=""),"",IF(L3="",IF(AND(Q3="",V3=""),"Belum ditempatkan",""),IF(O3="","CEK ID FIXTURE tidak ada di DAFTAR_FIXTURE",IF(M3="","CEK ZONA NO kosong",IF(ISNA(MATCH(O3&"|"&M3,LAYOUT!$E$2:$E$80,0)),"CEK ZONA NO di luar layout",IF(N3<>INDEX(LAYOUT!$D$2:$D$80,MATCH(O3&"|"&M3,LAYOUT!$E$2:$E$80,0)),"CEK JENIS ZONA",IF($D3="","Zona STOCK",IF($E3="","CEK SKU DESCRIPTION kosong","OK")))))))) | Q3: WLL-02 | R3: 2 | S3: Rak | T3: =IF(Q3="","",IFERROR(INDEX(DAFTAR_FIXTURE!$B$2:$B$51,MATCH(Q3,DAFTAR_FIXTURE!$A$2:$A$51,0)),"")) | U3: =IF(Q3="","",IF(T3="","CEK ID FIXTURE tidak ada di DAFTAR_FIXTURE",IF(R3="","CEK ZONA NO kosong",IF(ISNA(MATCH(T3&"|"&R3,LAYOUT!$E$2:$E$80,0)),"CEK ZONA NO di luar layout",IF(S3<>INDEX(LAYOUT!$D$2:$D$80,MATCH(T3&"|"&R3,LAYOUT!$E$2:$E$80,0)),"CEK JENIS ZONA",IF($D3="","Zona STOCK",IF($E3="","CEK SKU DESCRIPTION kosong","OK"))))))) | V3: GND-01 | W3: 1 | X3: Rak | Y3: =IF(V3="","",IFERROR(INDEX(DAFTAR_FIXTURE!$B$2:$B$51,MATCH(V3,DAFTAR_FIXTURE!$A$2:$A$51,0)),"")) | Z3: =IF(V3="","",IF(Y3="","CEK ID FIXTURE tidak ada di DAFTAR_FIXTURE",IF(W3="","CEK ZONA NO kosong",IF(ISNA(MATCH(Y3&"|"&W3,LAYOUT!$E$2:$E$80,0)),"CEK ZONA NO di luar layout",IF(X3<>INDEX(LAYOUT!$D$2:$D$80,MATCH(Y3&"|"&W3,LAYOUT!$E$2:$E$80,0)),"CEK JENIS ZONA",IF($D3="","Zona STOCK",IF($E3="","CEK SKU DESCRIPTION kosong","OK")))))))
A4: Homeware | B4: Cookware | C4: Casserole | D4: 10445960 | E4: CASSEROLE OVAL GOLD MARBLE W/LID 33CM | G4: MASAK | H4: B1. CASSEROLE | I4: GOLD MARBLE | L4: WLL-01 | M4: 2 | N4: Rak | O4: =IF(L4="","",IFERROR(INDEX(DAFTAR_FIXTURE!$B$2:$B$51,MATCH(L4,DAFTAR_FIXTURE!$A$2:$A$51,0)),"")) | P4: =IF(AND($D4="",L4=""),"",IF(L4="",IF(AND(Q4="",V4=""),"Belum ditempatkan",""),IF(O4="","CEK ID FIXTURE tidak ada di DAFTAR_FIXTURE",IF(M4="","CEK ZONA NO kosong",IF(ISNA(MATCH(O4&"|"&M4,LAYOUT!$E$2:$E$80,0)),"CEK ZONA NO di luar layout",IF(N4<>INDEX(LAYOUT!$D$2:$D$80,MATCH(O4&"|"&M4,LAYOUT!$E$2:$E$80,0)),"CEK JENIS ZONA",IF($D4="","Zona STOCK",IF($E4="","CEK SKU DESCRIPTION kosong","OK")))))))) | Q4: WLL-02 | R4: 2 | S4: Rak | T4: =IF(Q4="","",IFERROR(INDEX(DAFTAR_FIXTURE!$B$2:$B$51,MATCH(Q4,DAFTAR_FIXTURE!$A$2:$A$51,0)),"")) | U4: =IF(Q4="","",IF(T4="","CEK ID FIXTURE tidak ada di DAFTAR_FIXTURE",IF(R4="","CEK ZONA NO kosong",IF(ISNA(MATCH(T4&"|"&R4,LAYOUT!$E$2:$E$80,0)),"CEK ZONA NO di luar layout",IF(S4<>INDEX(LAYOUT!$D$2:$D$80,MATCH(T4&"|"&R4,LAYOUT!$E$2:$E$80,0)),"CEK JENIS ZONA",IF($D4="","Zona STOCK",IF($E4="","CEK SKU DESCRIPTION kosong","OK"))))))) | V4: GND-01 | W4: 1 | X4: Rak | Y4: =IF(V4="","",IFERROR(INDEX(DAFTAR_FIXTURE!$B$2:$B$51,MATCH(V4,DAFTAR_FIXTURE!$A$2:$A$51,0)),"")) | Z4: =IF(V4="","",IF(Y4="","CEK ID FIXTURE tidak ada di DAFTAR_FIXTURE",IF(W4="","CEK ZONA NO kosong",IF(ISNA(MATCH(Y4&"|"&W4,LAYOUT!$E$2:$E$80,0)),"CEK ZONA NO di luar layout",IF(X4<>INDEX(LAYOUT!$D$2:$D$80,MATCH(Y4&"|"&W4,LAYOUT!$E$2:$E$80,0)),"CEK JENIS ZONA",IF($D4="","Zona STOCK",IF($E4="","CEK SKU DESCRIPTION kosong","OK")))))))
A5: Homeware | B5: Cookware | C5: Casserole | D5: 10445961 | E5: CASSEROLE ROUND GOLD MARBLE W/LID 33CM | G5: MASAK | H5: B1. CASSEROLE | I5: GOLD MARBLE | L5: WLL-01 | M5: 2 | N5: Rak | O5: =IF(L5="","",IFERROR(INDEX(DAFTAR_FIXTURE!$B$2:$B$51,MATCH(L5,DAFTAR_FIXTURE!$A$2:$A$51,0)),"")) | P5: =IF(AND($D5="",L5=""),"",IF(L5="",IF(AND(Q5="",V5=""),"Belum ditempatkan",""),IF(O5="","CEK ID FIXTURE tidak ada di DAFTAR_FIXTURE",IF(M5="","CEK ZONA NO kosong",IF(ISNA(MATCH(O5&"|"&M5,LAYOUT!$E$2:$E$80,0)),"CEK ZONA NO di luar layout",IF(N5<>INDEX(LAYOUT!$D$2:$D$80,MATCH(O5&"|"&M5,LAYOUT!$E$2:$E$80,0)),"CEK JENIS ZONA",IF($D5="","Zona STOCK",IF($E5="","CEK SKU DESCRIPTION kosong","OK")))))))) | Q5: WLL-02 | R5: 2 | S5: Rak | T5: =IF(Q5="","",IFERROR(INDEX(DAFTAR_FIXTURE!$B$2:$B$51,MATCH(Q5,DAFTAR_FIXTURE!$A$2:$A$51,0)),"")) | U5: =IF(Q5="","",IF(T5="","CEK ID FIXTURE tidak ada di DAFTAR_FIXTURE",IF(R5="","CEK ZONA NO kosong",IF(ISNA(MATCH(T5&"|"&R5,LAYOUT!$E$2:$E$80,0)),"CEK ZONA NO di luar layout",IF(S5<>INDEX(LAYOUT!$D$2:$D$80,MATCH(T5&"|"&R5,LAYOUT!$E$2:$E$80,0)),"CEK JENIS ZONA",IF($D5="","Zona STOCK",IF($E5="","CEK SKU DESCRIPTION kosong","OK"))))))) | V5: GND-01 | W5: 1 | X5: Rak | Y5: =IF(V5="","",IFERROR(INDEX(DAFTAR_FIXTURE!$B$2:$B$51,MATCH(V5,DAFTAR_FIXTURE!$A$2:$A$51,0)),"")) | Z5: =IF(V5="","",IF(Y5="","CEK ID FIXTURE tidak ada di DAFTAR_FIXTURE",IF(W5="","CEK ZONA NO kosong",IF(ISNA(MATCH(Y5&"|"&W5,LAYOUT!$E$2:$E$80,0)),"CEK ZONA NO di luar layout",IF(X5<>INDEX(LAYOUT!$D$2:$D$80,MATCH(Y5&"|"&W5,LAYOUT!$E$2:$E$80,0)),"CEK JENIS ZONA",IF($D5="","Zona STOCK",IF($E5="","CEK SKU DESCRIPTION kosong","OK")))))))
A6: Homeware | B6: Cookware | C6: Casserole | D6: 10445962 | E6: CASSEROLE SQUARE GOLD MARBLE W/LID 33CM | G6: MASAK | H6: B1. CASSEROLE | I6: GOLD MARBLE | L6: WLL-01 | M6: 3 | N6: Rak | O6: =IF(L6="","",IFERROR(INDEX(DAFTAR_FIXTURE!$B$2:$B$51,MATCH(L6,DAFTAR_FIXTURE!$A$2:$A$51,0)),"")) | P6: =IF(AND($D6="",L6=""),"",IF(L6="",IF(AND(Q6="",V6=""),"Belum ditempatkan",""),IF(O6="","CEK ID FIXTURE tidak ada di DAFTAR_FIXTURE",IF(M6="","CEK ZONA NO kosong",IF(ISNA(MATCH(O6&"|"&M6,LAYOUT!$E$2:$E$80,0)),"CEK ZONA NO di luar layout",IF(N6<>INDEX(LAYOUT!$D$2:$D$80,MATCH(O6&"|"&M6,LAYOUT!$E$2:$E$80,0)),"CEK JENIS ZONA",IF($D6="","Zona STOCK",IF($E6="","CEK SKU DESCRIPTION kosong","OK")))))))) | Q6: WLL-02 | R6: 2 | S6: Rak | T6: =IF(Q6="","",IFERROR(INDEX(DAFTAR_FIXTURE!$B$2:$B$51,MATCH(Q6,DAFTAR_FIXTURE!$A$2:$A$51,0)),"")) | U6: =IF(Q6="","",IF(T6="","CEK ID FIXTURE tidak ada di DAFTAR_FIXTURE",IF(R6="","CEK ZONA NO kosong",IF(ISNA(MATCH(T6&"|"&R6,LAYOUT!$E$2:$E$80,0)),"CEK ZONA NO di luar layout",IF(S6<>INDEX(LAYOUT!$D$2:$D$80,MATCH(T6&"|"&R6,LAYOUT!$E$2:$E$80,0)),"CEK JENIS ZONA",IF($D6="","Zona STOCK",IF($E6="","CEK SKU DESCRIPTION kosong","OK"))))))) | V6: GND-01 | W6: 2 | X6: Rak | Y6: =IF(V6="","",IFERROR(INDEX(DAFTAR_FIXTURE!$B$2:$B$51,MATCH(V6,DAFTAR_FIXTURE!$A$2:$A$51,0)),"")) | Z6: =IF(V6="","",IF(Y6="","CEK ID FIXTURE tidak ada di DAFTAR_FIXTURE",IF(W6="","CEK ZONA NO kosong",IF(ISNA(MATCH(Y6&"|"&W6,LAYOUT!$E$2:$E$80,0)),"CEK ZONA NO di luar layout",IF(X6<>INDEX(LAYOUT!$D$2:$D$80,MATCH(Y6&"|"&W6,LAYOUT!$E$2:$E$80,0)),"CEK JENIS ZONA",IF($D6="","Zona STOCK",IF($E6="","CEK SKU DESCRIPTION kosong","OK")))))))
A7: Homeware | B7: Tableware | C7: Serving Set | D7: 10470029 | E7: SERVING SET W/RACK OCTAGON MARBLE (4) | G7: MAKAN | H7: A2. SERVINGWARE | I7: SERVING SET MARBLE | L7: WLL-01 | M7: 3 | N7: Rak | O7: =IF(L7="","",IFERROR(INDEX(DAFTAR_FIXTURE!$B$2:$B$51,MATCH(L7,DAFTAR_FIXTURE!$A$2:$A$51,0)),"")) | P7: =IF(AND($D7="",L7=""),"",IF(L7="",IF(AND(Q7="",V7=""),"Belum ditempatkan",""),IF(O7="","CEK ID FIXTURE tidak ada di DAFTAR_FIXTURE",IF(M7="","CEK ZONA NO kosong",IF(ISNA(MATCH(O7&"|"&M7,LAYOUT!$E$2:$E$80,0)),"CEK ZONA NO di luar layout",IF(N7<>INDEX(LAYOUT!$D$2:$D$80,MATCH(O7&"|"&M7,LAYOUT!$E$2:$E$80,0)),"CEK JENIS ZONA",IF($D7="","Zona STOCK",IF($E7="","CEK SKU DESCRIPTION kosong","OK")))))))) | Q7: WLL-02 | R7: 2 | S7: Rak | T7: =IF(Q7="","",IFERROR(INDEX(DAFTAR_FIXTURE!$B$2:$B$51,MATCH(Q7,DAFTAR_FIXTURE!$A$2:$A$51,0)),"")) | U7: =IF(Q7="","",IF(T7="","CEK ID FIXTURE tidak ada di DAFTAR_FIXTURE",IF(R7="","CEK ZONA NO kosong",IF(ISNA(MATCH(T7&"|"&R7,LAYOUT!$E$2:$E$80,0)),"CEK ZONA NO di luar layout",IF(S7<>INDEX(LAYOUT!$D$2:$D$80,MATCH(T7&"|"&R7,LAYOUT!$E$2:$E$80,0)),"CEK JENIS ZONA",IF($D7="","Zona STOCK",IF($E7="","CEK SKU DESCRIPTION kosong","OK"))))))) | V7: GND-01 | W7: 2 | X7: Rak | Y7: =IF(V7="","",IFERROR(INDEX(DAFTAR_FIXTURE!$B$2:$B$51,MATCH(V7,DAFTAR_FIXTURE!$A$2:$A$51,0)),"")) | Z7: =IF(V7="","",IF(Y7="","CEK ID FIXTURE tidak ada di DAFTAR_FIXTURE",IF(W7="","CEK ZONA NO kosong",IF(ISNA(MATCH(Y7&"|"&W7,LAYOUT!$E$2:$E$80,0)),"CEK ZONA NO di luar layout",IF(X7<>INDEX(LAYOUT!$D$2:$D$80,MATCH(Y7&"|"&W7,LAYOUT!$E$2:$E$80,0)),"CEK JENIS ZONA",IF($D7="","Zona STOCK",IF($E7="","CEK SKU DESCRIPTION kosong","OK")))))))
A8: Homeware | B8: Tableware | C8: Serving Set | D8: 10470030 | E8: SERVING SET RND DETACHABLE MARBLE (2) | G8: MAKAN | H8: A2. SERVINGWARE | I8: SERVING SET MARBLE | L8: WLL-01 | M8: 3 | N8: Rak | O8: =IF(L8="","",IFERROR(INDEX(DAFTAR_FIXTURE!$B$2:$B$51,MATCH(L8,DAFTAR_FIXTURE!$A$2:$A$51,0)),"")) | P8: =IF(AND($D8="",L8=""),"",IF(L8="",IF(AND(Q8="",V8=""),"Belum ditempatkan",""),IF(O8="","CEK ID FIXTURE tidak ada di DAFTAR_FIXTURE",IF(M8="","CEK ZONA NO kosong",IF(ISNA(MATCH(O8&"|"&M8,LAYOUT!$E$2:$E$80,0)),"CEK ZONA NO di luar layout",IF(N8<>INDEX(LAYOUT!$D$2:$D$80,MATCH(O8&"|"&M8,LAYOUT!$E$2:$E$80,0)),"CEK JENIS ZONA",IF($D8="","Zona STOCK",IF($E8="","CEK SKU DESCRIPTION kosong","OK")))))))) | Q8: WLL-02 | R8: 3 | S8: Rak | T8: =IF(Q8="","",IFERROR(INDEX(DAFTAR_FIXTURE!$B$2:$B$51,MATCH(Q8,DAFTAR_FIXTURE!$A$2:$A$51,0)),"")) | U8: =IF(Q8="","",IF(T8="","CEK ID FIXTURE tidak ada di DAFTAR_FIXTURE",IF(R8="","CEK ZONA NO kosong",IF(ISNA(MATCH(T8&"|"&R8,LAYOUT!$E$2:$E$80,0)),"CEK ZONA NO di luar layout",IF(S8<>INDEX(LAYOUT!$D$2:$D$80,MATCH(T8&"|"&R8,LAYOUT!$E$2:$E$80,0)),"CEK JENIS ZONA",IF($D8="","Zona STOCK",IF($E8="","CEK SKU DESCRIPTION kosong","OK"))))))) | V8: GND-01 | W8: 2 | X8: Rak | Y8: =IF(V8="","",IFERROR(INDEX(DAFTAR_FIXTURE!$B$2:$B$51,MATCH(V8,DAFTAR_FIXTURE!$A$2:$A$51,0)),"")) | Z8: =IF(V8="","",IF(Y8="","CEK ID FIXTURE tidak ada di DAFTAR_FIXTURE",IF(W8="","CEK ZONA NO kosong",IF(ISNA(MATCH(Y8&"|"&W8,LAYOUT!$E$2:$E$80,0)),"CEK ZONA NO di luar layout",IF(X8<>INDEX(LAYOUT!$D$2:$D$80,MATCH(Y8&"|"&W8,LAYOUT!$E$2:$E$80,0)),"CEK JENIS ZONA",IF($D8="","Zona STOCK",IF($E8="","CEK SKU DESCRIPTION kosong","OK")))))))
A9: Homeware | B9: Tableware | C9: Serving Set | D9: 10470031 | E9: SERVING SET W/RACK SQR MARBLE BLACK (3) | G9: MAKAN | H9: A2. SERVINGWARE | I9: SERVING SET MARBLE | L9: WLL-01 | M9: 4 | N9: Rak | O9: =IF(L9="","",IFERROR(INDEX(DAFTAR_FIXTURE!$B$2:$B$51,MATCH(L9,DAFTAR_FIXTURE!$A$2:$A$51,0)),"")) | P9: =IF(AND($D9="",L9=""),"",IF(L9="",IF(AND(Q9="",V9=""),"Belum ditempatkan",""),IF(O9="","CEK ID FIXTURE tidak ada di DAFTAR_FIXTURE",IF(M9="","CEK ZONA NO kosong",IF(ISNA(MATCH(O9&"|"&M9,LAYOUT!$E$2:$E$80,0)),"CEK ZONA NO di luar layout",IF(N9<>INDEX(LAYOUT!$D$2:$D$80,MATCH(O9&"|"&M9,LAYOUT!$E$2:$E$80,0)),"CEK JENIS ZONA",IF($D9="","Zona STOCK",IF($E9="","CEK SKU DESCRIPTION kosong","OK")))))))) | Q9: WLL-02 | R9: 3 | S9: Rak | T9: =IF(Q9="","",IFERROR(INDEX(DAFTAR_FIXTURE!$B$2:$B$51,MATCH(Q9,DAFTAR_FIXTURE!$A$2:$A$51,0)),"")) | U9: =IF(Q9="","",IF(T9="","CEK ID FIXTURE tidak ada di DAFTAR_FIXTURE",IF(R9="","CEK ZONA NO kosong",IF(ISNA(MATCH(T9&"|"&R9,LAYOUT!$E$2:$E$80,0)),"CEK ZONA NO di luar layout",IF(S9<>INDEX(LAYOUT!$D$2:$D$80,MATCH(T9&"|"&R9,LAYOUT!$E$2:$E$80,0)),"CEK JENIS ZONA",IF($D9="","Zona STOCK",IF($E9="","CEK SKU DESCRIPTION kosong","OK"))))))) | Y9: =IF(V9="","",IFERROR(INDEX(DAFTAR_FIXTURE!$B$2:$B$51,MATCH(V9,DAFTAR_FIXTURE!$A$2:$A$51,0)),"")) | Z9: =IF(V9="","",IF(Y9="","CEK ID FIXTURE tidak ada di DAFTAR_FIXTURE",IF(W9="","CEK ZONA NO kosong",IF(ISNA(MATCH(Y9&"|"&W9,LAYOUT!$E$2:$E$80,0)),"CEK ZONA NO di luar layout",IF(X9<>INDEX(LAYOUT!$D$2:$D$80,MATCH(Y9&"|"&W9,LAYOUT!$E$2:$E$80,0)),"CEK JENIS ZONA",IF($D9="","Zona STOCK",IF($E9="","CEK SKU DESCRIPTION kosong","OK")))))))
A10: Homeware | B10: Tableware | C10: Serving Set | D10: 10470032 | E10: SERVING SET W/RACK STACK WHITE (3) | G10: MAKAN | H10: A2. SERVINGWARE | I10: SERVING SET MARBLE | L10: WLL-01 | M10: 4 | N10: Rak | O10: =IF(L10="","",IFERROR(INDEX(DAFTAR_FIXTURE!$B$2:$B$51,MATCH(L10,DAFTAR_FIXTURE!$A$2:$A$51,0)),"")) | P10: =IF(AND($D10="",L10=""),"",IF(L10="",IF(AND(Q10="",V10=""),"Belum ditempatkan",""),IF(O10="","CEK ID FIXTURE tidak ada di DAFTAR_FIXTURE",IF(M10="","CEK ZONA NO kosong",IF(ISNA(MATCH(O10&"|"&M10,LAYOUT!$E$2:$E$80,0)),"CEK ZONA NO di luar layout",IF(N10<>INDEX(LAYOUT!$D$2:$D$80,MATCH(O10&"|"&M10,LAYOUT!$E$2:$E$80,0)),"CEK JENIS ZONA",IF($D10="","Zona STOCK",IF($E10="","CEK SKU DESCRIPTION kosong","OK")))))))) | Q10: WLL-02 | R10: 3 | S10: Rak | T10: =IF(Q10="","",IFERROR(INDEX(DAFTAR_FIXTURE!$B$2:$B$51,MATCH(Q10,DAFTAR_FIXTURE!$A$2:$A$51,0)),"")) | U10: =IF(Q10="","",IF(T10="","CEK ID FIXTURE tidak ada di DAFTAR_FIXTURE",IF(R10="","CEK ZONA NO kosong",IF(ISNA(MATCH(T10&"|"&R10,LAYOUT!$E$2:$E$80,0)),"CEK ZONA NO di luar layout",IF(S10<>INDEX(LAYOUT!$D$2:$D$80,MATCH(T10&"|"&R10,LAYOUT!$E$2:$E$80,0)),"CEK JENIS ZONA",IF($D10="","Zona STOCK",IF($E10="","CEK SKU DESCRIPTION kosong","OK"))))))) | Y10: =IF(V10="","",IFERROR(INDEX(DAFTAR_FIXTURE!$B$2:$B$51,MATCH(V10,DAFTAR_FIXTURE!$A$2:$A$51,0)),"")) | Z10: =IF(V10="","",IF(Y10="","CEK ID FIXTURE tidak ada di DAFTAR_FIXTURE",IF(W10="","CEK ZONA NO kosong",IF(ISNA(MATCH(Y10&"|"&W10,LAYOUT!$E$2:$E$80,0)),"CEK ZONA NO di luar layout",IF(X10<>INDEX(LAYOUT!$D$2:$D$80,MATCH(Y10&"|"&W10,LAYOUT!$E$2:$E$80,0)),"CEK JENIS ZONA",IF($D10="","Zona STOCK",IF($E10="","CEK SKU DESCRIPTION kosong","OK")))))))
A11: Homeware | B11: Tableware | C11: Serving Set | D11: 10470033 | E11: SERVING SET W/RACK CIRCLE BLACK (3) | G11: MAKAN | H11: A2. SERVINGWARE | I11: SERVING SET MARBLE | L11: WLL-01 | M11: 4 | N11: Rak | O11: =IF(L11="","",IFERROR(INDEX(DAFTAR_FIXTURE!$B$2:$B$51,MATCH(L11,DAFTAR_FIXTURE!$A$2:$A$51,0)),"")) | P11: =IF(AND($D11="",L11=""),"",IF(L11="",IF(AND(Q11="",V11=""),"Belum ditempatkan",""),IF(O11="","CEK ID FIXTURE tidak ada di DAFTAR_FIXTURE",IF(M11="","CEK ZONA NO kosong",IF(ISNA(MATCH(O11&"|"&M11,LAYOUT!$E$2:$E$80,0)),"CEK ZONA NO di luar layout",IF(N11<>INDEX(LAYOUT!$D$2:$D$80,MATCH(O11&"|"&M11,LAYOUT!$E$2:$E$80,0)),"CEK JENIS ZONA",IF($D11="","Zona STOCK",IF($E11="","CEK SKU DESCRIPTION kosong","OK")))))))) | Q11: WLL-02 | R11: 3 | S11: Rak | T11: =IF(Q11="","",IFERROR(INDEX(DAFTAR_FIXTURE!$B$2:$B$51,MATCH(Q11,DAFTAR_FIXTURE!$A$2:$A$51,0)),"")) | U11: =IF(Q11="","",IF(T11="","CEK ID FIXTURE tidak ada di DAFTAR_FIXTURE",IF(R11="","CEK ZONA NO kosong",IF(ISNA(MATCH(T11&"|"&R11,LAYOUT!$E$2:$E$80,0)),"CEK ZONA NO di luar layout",IF(S11<>INDEX(LAYOUT!$D$2:$D$80,MATCH(T11&"|"&R11,LAYOUT!$E$2:$E$80,0)),"CEK JENIS ZONA",IF($D11="","Zona STOCK",IF($E11="","CEK SKU DESCRIPTION kosong","OK"))))))) | Y11: =IF(V11="","",IFERROR(INDEX(DAFTAR_FIXTURE!$B$2:$B$51,MATCH(V11,DAFTAR_FIXTURE!$A$2:$A$51,0)),"")) | Z11: =IF(V11="","",IF(Y11="","CEK ID FIXTURE tidak ada di DAFTAR_FIXTURE",IF(W11="","CEK ZONA NO kosong",IF(ISNA(MATCH(Y11&"|"&W11,LAYOUT!$E$2:$E$80,0)),"CEK ZONA NO di luar layout",IF(X11<>INDEX(LAYOUT!$D$2:$D$80,MATCH(Y11&"|"&W11,LAYOUT!$E$2:$E$80,0)),"CEK JENIS ZONA",IF($D11="","Zona STOCK",IF($E11="","CEK SKU DESCRIPTION kosong","OK")))))))
A12: Homeware | B12: Storage | C12: Food Storage | D12: 10680419 | E12: MOSQUE DOME GLASS JAR SET OF 3 450ML | G12: PENYIMPANAN | H12: E4. CANISTER | I12: GLASS FANCY | L12: WLL-01 | M12: 5 | N12: Rak | O12: =IF(L12="","",IFERROR(INDEX(DAFTAR_FIXTURE!$B$2:$B$51,MATCH(L12,DAFTAR_FIXTURE!$A$2:$A$51,0)),"")) | P12: =IF(AND($D12="",L12=""),"",IF(L12="",IF(AND(Q12="",V12=""),"Belum ditempatkan",""),IF(O12="","CEK ID FIXTURE tidak ada di DAFTAR_FIXTURE",IF(M12="","CEK ZONA NO kosong",IF(ISNA(MATCH(O12&"|"&M12,LAYOUT!$E$2:$E$80,0)),"CEK ZONA NO di luar layout",IF(N12<>INDEX(LAYOUT!$D$2:$D$80,MATCH(O12&"|"&M12,LAYOUT!$E$2:$E$80,0)),"CEK JENIS ZONA",IF($D12="","Zona STOCK",IF($E12="","CEK SKU DESCRIPTION kosong","OK")))))))) | Q12: GND-01 | R12: 4 | S12: Rak | T12: =IF(Q12="","",IFERROR(INDEX(DAFTAR_FIXTURE!$B$2:$B$51,MATCH(Q12,DAFTAR_FIXTURE!$A$2:$A$51,0)),"")) | U12: =IF(Q12="","",IF(T12="","CEK ID FIXTURE tidak ada di DAFTAR_FIXTURE",IF(R12="","CEK ZONA NO kosong",IF(ISNA(MATCH(T12&"|"&R12,LAYOUT!$E$2:$E$80,0)),"CEK ZONA NO di luar layout",IF(S12<>INDEX(LAYOUT!$D$2:$D$80,MATCH(T12&"|"&R12,LAYOUT!$E$2:$E$80,0)),"CEK JENIS ZONA",IF($D12="","Zona STOCK",IF($E12="","CEK SKU DESCRIPTION kosong","OK"))))))) | Y12: =IF(V12="","",IFERROR(INDEX(DAFTAR_FIXTURE!$B$2:$B$51,MATCH(V12,DAFTAR_FIXTURE!$A$2:$A$51,0)),"")) | Z12: =IF(V12="","",IF(Y12="","CEK ID FIXTURE tidak ada di DAFTAR_FIXTURE",IF(W12="","CEK ZONA NO kosong",IF(ISNA(MATCH(Y12&"|"&W12,LAYOUT!$E$2:$E$80,0)),"CEK ZONA NO di luar layout",IF(X12<>INDEX(LAYOUT!$D$2:$D$80,MATCH(Y12&"|"&W12,LAYOUT!$E$2:$E$80,0)),"CEK JENIS ZONA",IF($D12="","Zona STOCK",IF($E12="","CEK SKU DESCRIPTION kosong","OK")))))))
A13: Homeware | B13: Drinkware | C13: Glassware | D13: 10099887 | E13: ELAN WATER GLASS SET 414ML (6) | G13: MAKAN | H13: A1. GLASSWARE | I13: ELAN | L13: WLL-01 | M13: 6 | N13: Rak | O13: =IF(L13="","",IFERROR(INDEX(DAFTAR_FIXTURE!$B$2:$B$51,MATCH(L13,DAFTAR_FIXTURE!$A$2:$A$51,0)),"")) | P13: =IF(AND($D13="",L13=""),"",IF(L13="",IF(AND(Q13="",V13=""),"Belum ditempatkan",""),IF(O13="","CEK ID FIXTURE tidak ada di DAFTAR_FIXTURE",IF(M13="","CEK ZONA NO kosong",IF(ISNA(MATCH(O13&"|"&M13,LAYOUT!$E$2:$E$80,0)),"CEK ZONA NO di luar layout",IF(N13<>INDEX(LAYOUT!$D$2:$D$80,MATCH(O13&"|"&M13,LAYOUT!$E$2:$E$80,0)),"CEK JENIS ZONA",IF($D13="","Zona STOCK",IF($E13="","CEK SKU DESCRIPTION kosong","OK")))))))) | T13: =IF(Q13="","",IFERROR(INDEX(DAFTAR_FIXTURE!$B$2:$B$51,MATCH(Q13,DAFTAR_FIXTURE!$A$2:$A$51,0)),"")) | U13: =IF(Q13="","",IF(T13="","CEK ID FIXTURE tidak ada di DAFTAR_FIXTURE",IF(R13="","CEK ZONA NO kosong",IF(ISNA(MATCH(T13&"|"&R13,LAYOUT!$E$2:$E$80,0)),"CEK ZONA NO di luar layout",IF(S13<>INDEX(LAYOUT!$D$2:$D$80,MATCH(T13&"|"&R13,LAYOUT!$E$2:$E$80,0)),"CEK JENIS ZONA",IF($D13="","Zona STOCK",IF($E13="","CEK SKU DESCRIPTION kosong","OK"))))))) | Y13: =IF(V13="","",IFERROR(INDEX(DAFTAR_FIXTURE!$B$2:$B$51,MATCH(V13,DAFTAR_FIXTURE!$A$2:$A$51,0)),"")) | Z13: =IF(V13="","",IF(Y13="","CEK ID FIXTURE tidak ada di DAFTAR_FIXTURE",IF(W13="","CEK ZONA NO kosong",IF(ISNA(MATCH(Y13&"|"&W13,LAYOUT!$E$2:$E$80,0)),"CEK ZONA NO di luar layout",IF(X13<>INDEX(LAYOUT!$D$2:$D$80,MATCH(Y13&"|"&W13,LAYOUT!$E$2:$E$80,0)),"CEK JENIS ZONA",IF($D13="","Zona STOCK",IF($E13="","CEK SKU DESCRIPTION kosong","OK")))))))
A14: Homeware | B14: Tableware | C14: Plates & Bowls | D14: 238181 | E14: COUPE PLATE 16 CM SIMPLE PLUS | L14: WLL-02 | M14: 1 | N14: Rak | O14: =IF(L14="","",IFERROR(INDEX(DAFTAR_FIXTURE!$B$2:$B$51,MATCH(L14,DAFTAR_FIXTURE!$A$2:$A$51,0)),"")) | P14: =IF(AND($D14="",L14=""),"",IF(L14="",IF(AND(Q14="",V14=""),"Belum ditempatkan",""),IF(O14="","CEK ID FIXTURE tidak ada di DAFTAR_FIXTURE",IF(M14="","CEK ZONA NO kosong",IF(ISNA(MATCH(O14&"|"&M14,LAYOUT!$E$2:$E$80,0)),"CEK ZONA NO di luar layout",IF(N14<>INDEX(LAYOUT!$D$2:$D$80,MATCH(O14&"|"&M14,LAYOUT!$E$2:$E$80,0)),"CEK JENIS ZONA",IF($D14="","Zona STOCK",IF($E14="","CEK SKU DESCRIPTION kosong","OK")))))))) | T14: =IF(Q14="","",IFERROR(INDEX(DAFTAR_FIXTURE!$B$2:$B$51,MATCH(Q14,DAFTAR_FIXTURE!$A$2:$A$51,0)),"")) | U14: =IF(Q14="","",IF(T14="","CEK ID FIXTURE tidak ada di DAFTAR_FIXTURE",IF(R14="","CEK ZONA NO kosong",IF(ISNA(MATCH(T14&"|"&R14,LAYOUT!$E$2:$E$80,0)),"CEK ZONA NO di luar layout",IF(S14<>INDEX(LAYOUT!$D$2:$D$80,MATCH(T14&"|"&R14,LAYOUT!$E$2:$E$80,0)),"CEK JENIS ZONA",IF($D14="","Zona STOCK",IF($E14="","CEK SKU DESCRIPTION kosong","OK"))))))) | Y14: =IF(V14="","",IFERROR(INDEX(DAFTAR_FIXTURE!$B$2:$B$51,MATCH(V14,DAFTAR_FIXTURE!$A$2:$A$51,0)),"")) | Z14: =IF(V14="","",IF(Y14="","CEK ID FIXTURE tidak ada di DAFTAR_FIXTURE",IF(W14="","CEK ZONA NO kosong",IF(ISNA(MATCH(Y14&"|"&W14,LAYOUT!$E$2:$E$80,0)),"CEK ZONA NO di luar layout",IF(X14<>INDEX(LAYOUT!$D$2:$D$80,MATCH(Y14&"|"&W14,LAYOUT!$E$2:$E$80,0)),"CEK JENIS ZONA",IF($D14="","Zona STOCK",IF($E14="","CEK SKU DESCRIPTION kosong","OK")))))))
A15: Homeware | B15: Cookware | C15: Casserole | D15: 10606307 | E15: CASSEROLE RECT MARBLE W/RACK WHT 38CM | G15: MASAK | H15: B1. CASSEROLE | I15: MARBLE W/RACK | L15: WLL-02 | M15: 3 | N15: Rak | O15: =IF(L15="","",IFERROR(INDEX(DAFTAR_FIXTURE!$B$2:$B$51,MATCH(L15,DAFTAR_FIXTURE!$A$2:$A$51,0)),"")) | P15: =IF(AND($D15="",L15=""),"",IF(L15="",IF(AND(Q15="",V15=""),"Belum ditempatkan",""),IF(O15="","CEK ID FIXTURE tidak ada di DAFTAR_FIXTURE",IF(M15="","CEK ZONA NO kosong",IF(ISNA(MATCH(O15&"|"&M15,LAYOUT!$E$2:$E$80,0)),"CEK ZONA NO di luar layout",IF(N15<>INDEX(LAYOUT!$D$2:$D$80,MATCH(O15&"|"&M15,LAYOUT!$E$2:$E$80,0)),"CEK JENIS ZONA",IF($D15="","Zona STOCK",IF($E15="","CEK SKU DESCRIPTION kosong","OK")))))))) | T15: =IF(Q15="","",IFERROR(INDEX(DAFTAR_FIXTURE!$B$2:$B$51,MATCH(Q15,DAFTAR_FIXTURE!$A$2:$A$51,0)),"")) | U15: =IF(Q15="","",IF(T15="","CEK ID FIXTURE tidak ada di DAFTAR_FIXTURE",IF(R15="","CEK ZONA NO kosong",IF(ISNA(MATCH(T15&"|"&R15,LAYOUT!$E$2:$E$80,0)),"CEK ZONA NO di luar layout",IF(S15<>INDEX(LAYOUT!$D$2:$D$80,MATCH(T15&"|"&R15,LAYOUT!$E$2:$E$80,0)),"CEK JENIS ZONA",IF($D15="","Zona STOCK",IF($E15="","CEK SKU DESCRIPTION kosong","OK"))))))) | Y15: =IF(V15="","",IFERROR(INDEX(DAFTAR_FIXTURE!$B$2:$B$51,MATCH(V15,DAFTAR_FIXTURE!$A$2:$A$51,0)),"")) | Z15: =IF(V15="","",IF(Y15="","CEK ID FIXTURE tidak ada di DAFTAR_FIXTURE",IF(W15="","CEK ZONA NO kosong",IF(ISNA(MATCH(Y15&"|"&W15,LAYOUT!$E$2:$E$80,0)),"CEK ZONA NO di luar layout",IF(X15<>INDEX(LAYOUT!$D$2:$D$80,MATCH(Y15&"|"&W15,LAYOUT!$E$2:$E$80,0)),"CEK JENIS ZONA",IF($D15="","Zona STOCK",IF($E15="","CEK SKU DESCRIPTION kosong","OK")))))))
A16: Homeware | B16: Tableware | C16: Serving Set | D16: 10681571 | E16: SERVING GLASS SQR PLATER ZEVY GOLD | G16: MAKAN | H16: A2. SERVINGWARE | I16: W/GOLD RACK GLASS | L16: WLL-02 | M16: 4 | N16: Rak | O16: =IF(L16="","",IFERROR(INDEX(DAFTAR_FIXTURE!$B$2:$B$51,MATCH(L16,DAFTAR_FIXTURE!$A$2:$A$51,0)),"")) | P16: =IF(AND($D16="",L16=""),"",IF(L16="",IF(AND(Q16="",V16=""),"Belum ditempatkan",""),IF(O16="","CEK ID FIXTURE tidak ada di DAFTAR_FIXTURE",IF(M16="","CEK ZONA NO kosong",IF(ISNA(MATCH(O16&"|"&M16,LAYOUT!$E$2:$E$80,0)),"CEK ZONA NO di luar layout",IF(N16<>INDEX(LAYOUT!$D$2:$D$80,MATCH(O16&"|"&M16,LAYOUT!$E$2:$E$80,0)),"CEK JENIS ZONA",IF($D16="","Zona STOCK",IF($E16="","CEK SKU DESCRIPTION kosong","OK")))))))) | Q16: GND-01 | R16: 3 | S16: Rak | T16: =IF(Q16="","",IFERROR(INDEX(DAFTAR_FIXTURE!$B$2:$B$51,MATCH(Q16,DAFTAR_FIXTURE!$A$2:$A$51,0)),"")) | U16: =IF(Q16="","",IF(T16="","CEK ID FIXTURE tidak ada di DAFTAR_FIXTURE",IF(R16="","CEK ZONA NO kosong",IF(ISNA(MATCH(T16&"|"&R16,LAYOUT!$E$2:$E$80,0)),"CEK ZONA NO di luar layout",IF(S16<>INDEX(LAYOUT!$D$2:$D$80,MATCH(T16&"|"&R16,LAYOUT!$E$2:$E$80,0)),"CEK JENIS ZONA",IF($D16="","Zona STOCK",IF($E16="","CEK SKU DESCRIPTION kosong","OK"))))))) | Y16: =IF(V16="","",IFERROR(INDEX(DAFTAR_FIXTURE!$B$2:$B$51,MATCH(V16,DAFTAR_FIXTURE!$A$2:$A$51,0)),"")) | Z16: =IF(V16="","",IF(Y16="","CEK ID FIXTURE tidak ada di DAFTAR_FIXTURE",IF(W16="","CEK ZONA NO kosong",IF(ISNA(MATCH(Y16&"|"&W16,LAYOUT!$E$2:$E$80,0)),"CEK ZONA NO di luar layout",IF(X16<>INDEX(LAYOUT!$D$2:$D$80,MATCH(Y16&"|"&W16,LAYOUT!$E$2:$E$80,0)),"CEK JENIS ZONA",IF($D16="","Zona STOCK",IF($E16="","CEK SKU DESCRIPTION kosong","OK")))))))
A17: Homeware | B17: Cookware | C17: Pots & Pans | D17: 10421603 | E17: KINGSTON SAUCEPAN WITH LID 16CM GREEN | G17: MASAK | H17: B2. COOKWARE | I17: KINGSTON | L17: WLL-03 | M17: 1 | N17: Gantungan | O17: =IF(L17="","",IFERROR(INDEX(DAFTAR_FIXTURE!$B$2:$B$51,MATCH(L17,DAFTAR_FIXTURE!$A$2:$A$51,0)),"")) | P17: =IF(AND($D17="",L17=""),"",IF(L17="",IF(AND(Q17="",V17=""),"Belum ditempatkan",""),IF(O17="","CEK ID FIXTURE tidak ada di DAFTAR_FIXTURE",IF(M17="","CEK ZONA NO kosong",IF(ISNA(MATCH(O17&"|"&M17,LAYOUT!$E$2:$E$80,0)),"CEK ZONA NO di luar layout",IF(N17<>INDEX(LAYOUT!$D$2:$D$80,MATCH(O17&"|"&M17,LAYOUT!$E$2:$E$80,0)),"CEK JENIS ZONA",IF($D17="","Zona STOCK",IF($E17="","CEK SKU DESCRIPTION kosong","OK")))))))) | Q17: WLL-03 | R17: 2 | S17: Gantungan | T17: =IF(Q17="","",IFERROR(INDEX(DAFTAR_FIXTURE!$B$2:$B$51,MATCH(Q17,DAFTAR_FIXTURE!$A$2:$A$51,0)),"")) | U17: =IF(Q17="","",IF(T17="","CEK ID FIXTURE tidak ada di DAFTAR_FIXTURE",IF(R17="","CEK ZONA NO kosong",IF(ISNA(MATCH(T17&"|"&R17,LAYOUT!$E$2:$E$80,0)),"CEK ZONA NO di luar layout",IF(S17<>INDEX(LAYOUT!$D$2:$D$80,MATCH(T17&"|"&R17,LAYOUT!$E$2:$E$80,0)),"CEK JENIS ZONA",IF($D17="","Zona STOCK",IF($E17="","CEK SKU DESCRIPTION kosong","OK"))))))) | V17: GND-03 | W17: 1 | X17: Rak | Y17: =IF(V17="","",IFERROR(INDEX(DAFTAR_FIXTURE!$B$2:$B$51,MATCH(V17,DAFTAR_FIXTURE!$A$2:$A$51,0)),"")) | Z17: =IF(V17="","",IF(Y17="","CEK ID FIXTURE tidak ada di DAFTAR_FIXTURE",IF(W17="","CEK ZONA NO kosong",IF(ISNA(MATCH(Y17&"|"&W17,LAYOUT!$E$2:$E$80,0)),"CEK ZONA NO di luar layout",IF(X17<>INDEX(LAYOUT!$D$2:$D$80,MATCH(Y17&"|"&W17,LAYOUT!$E$2:$E$80,0)),"CEK JENIS ZONA",IF($D17="","Zona STOCK",IF($E17="","CEK SKU DESCRIPTION kosong","OK")))))))
A18: Homeware | B18: Cookware | C18: Pots & Pans | D18: 10421608 | E18: KINGSTON CASSEROLE WITH LID 20 CM GREEN | G18: MASAK | H18: B2. COOKWARE | I18: KINGSTON | L18: WLL-03 | M18: 1 | N18: Gantungan | O18: =IF(L18="","",IFERROR(INDEX(DAFTAR_FIXTURE!$B$2:$B$51,MATCH(L18,DAFTAR_FIXTURE!$A$2:$A$51,0)),"")) | P18: =IF(AND($D18="",L18=""),"",IF(L18="",IF(AND(Q18="",V18=""),"Belum ditempatkan",""),IF(O18="","CEK ID FIXTURE tidak ada di DAFTAR_FIXTURE",IF(M18="","CEK ZONA NO kosong",IF(ISNA(MATCH(O18&"|"&M18,LAYOUT!$E$2:$E$80,0)),"CEK ZONA NO di luar layout",IF(N18<>INDEX(LAYOUT!$D$2:$D$80,MATCH(O18&"|"&M18,LAYOUT!$E$2:$E$80,0)),"CEK JENIS ZONA",IF($D18="","Zona STOCK",IF($E18="","CEK SKU DESCRIPTION kosong","OK")))))))) | Q18: WLL-03 | R18: 2 | S18: Gantungan | T18: =IF(Q18="","",IFERROR(INDEX(DAFTAR_FIXTURE!$B$2:$B$51,MATCH(Q18,DAFTAR_FIXTURE!$A$2:$A$51,0)),"")) | U18: =IF(Q18="","",IF(T18="","CEK ID FIXTURE tidak ada di DAFTAR_FIXTURE",IF(R18="","CEK ZONA NO kosong",IF(ISNA(MATCH(T18&"|"&R18,LAYOUT!$E$2:$E$80,0)),"CEK ZONA NO di luar layout",IF(S18<>INDEX(LAYOUT!$D$2:$D$80,MATCH(T18&"|"&R18,LAYOUT!$E$2:$E$80,0)),"CEK JENIS ZONA",IF($D18="","Zona STOCK",IF($E18="","CEK SKU DESCRIPTION kosong","OK"))))))) | V18: GND-03 | W18: 1 | X18: Rak | Y18: =IF(V18="","",IFERROR(INDEX(DAFTAR_FIXTURE!$B$2:$B$51,MATCH(V18,DAFTAR_FIXTURE!$A$2:$A$51,0)),"")) | Z18: =IF(V18="","",IF(Y18="","CEK ID FIXTURE tidak ada di DAFTAR_FIXTURE",IF(W18="","CEK ZONA NO kosong",IF(ISNA(MATCH(Y18&"|"&W18,LAYOUT!$E$2:$E$80,0)),"CEK ZONA NO di luar layout",IF(X18<>INDEX(LAYOUT!$D$2:$D$80,MATCH(Y18&"|"&W18,LAYOUT!$E$2:$E$80,0)),"CEK JENIS ZONA",IF($D18="","Zona STOCK",IF($E18="","CEK SKU DESCRIPTION kosong","OK")))))))
A19: Homeware | B19: Cookware | C19: Pots & Pans | D19: 10421610 | E19: KINGSTON GRILL PAN 24CM GREEN | G19: MASAK | H19: B2. COOKWARE | I19: KINGSTON | L19: WLL-03 | M19: 1 | N19: Gantungan | O19: =IF(L19="","",IFERROR(INDEX(DAFTAR_FIXTURE!$B$2:$B$51,MATCH(L19,DAFTAR_FIXTURE!$A$2:$A$51,0)),"")) | P19: =IF(AND($D19="",L19=""),"",IF(L19="",IF(AND(Q19="",V19=""),"Belum ditempatkan",""),IF(O19="","CEK ID FIXTURE tidak ada di DAFTAR_FIXTURE",IF(M19="","CEK ZONA NO kosong",IF(ISNA(MATCH(O19&"|"&M19,LAYOUT!$E$2:$E$80,0)),"CEK ZONA NO di luar layout",IF(N19<>INDEX(LAYOUT!$D$2:$D$80,MATCH(O19&"|"&M19,LAYOUT!$E$2:$E$80,0)),"CEK JENIS ZONA",IF($D19="","Zona STOCK",IF($E19="","CEK SKU DESCRIPTION kosong","OK")))))))) | Q19: WLL-03 | R19: 2 | S19: Gantungan | T19: =IF(Q19="","",IFERROR(INDEX(DAFTAR_FIXTURE!$B$2:$B$51,MATCH(Q19,DAFTAR_FIXTURE!$A$2:$A$51,0)),"")) | U19: =IF(Q19="","",IF(T19="","CEK ID FIXTURE tidak ada di DAFTAR_FIXTURE",IF(R19="","CEK ZONA NO kosong",IF(ISNA(MATCH(T19&"|"&R19,LAYOUT!$E$2:$E$80,0)),"CEK ZONA NO di luar layout",IF(S19<>INDEX(LAYOUT!$D$2:$D$80,MATCH(T19&"|"&R19,LAYOUT!$E$2:$E$80,0)),"CEK JENIS ZONA",IF($D19="","Zona STOCK",IF($E19="","CEK SKU DESCRIPTION kosong","OK"))))))) | V19: GND-03 | W19: 1 | X19: Rak | Y19: =IF(V19="","",IFERROR(INDEX(DAFTAR_FIXTURE!$B$2:$B$51,MATCH(V19,DAFTAR_FIXTURE!$A$2:$A$51,0)),"")) | Z19: =IF(V19="","",IF(Y19="","CEK ID FIXTURE tidak ada di DAFTAR_FIXTURE",IF(W19="","CEK ZONA NO kosong",IF(ISNA(MATCH(Y19&"|"&W19,LAYOUT!$E$2:$E$80,0)),"CEK ZONA NO di luar layout",IF(X19<>INDEX(LAYOUT!$D$2:$D$80,MATCH(Y19&"|"&W19,LAYOUT!$E$2:$E$80,0)),"CEK JENIS ZONA",IF($D19="","Zona STOCK",IF($E19="","CEK SKU DESCRIPTION kosong","OK")))))))
A20: Homeware | B20: Cookware | C20: Pots & Pans | D20: 10421614 | E20: KIRA WOK 2 HANDLE W LID AND UTENSIL BRN | G20: MASAK | H20: B2. COOKWARE | I20: KIRA | L20: WLL-03 | M20: 1 | N20: Gantungan | O20: =IF(L20="","",IFERROR(INDEX(DAFTAR_FIXTURE!$B$2:$B$51,MATCH(L20,DAFTAR_FIXTURE!$A$2:$A$51,0)),"")) | P20: =IF(AND($D20="",L20=""),"",IF(L20="",IF(AND(Q20="",V20=""),"Belum ditempatkan",""),IF(O20="","CEK ID FIXTURE tidak ada di DAFTAR_FIXTURE",IF(M20="","CEK ZONA NO kosong",IF(ISNA(MATCH(O20&"|"&M20,LAYOUT!$E$2:$E$80,0)),"CEK ZONA NO di luar layout",IF(N20<>INDEX(LAYOUT!$D$2:$D$80,MATCH(O20&"|"&M20,LAYOUT!$E$2:$E$80,0)),"CEK JENIS ZONA",IF($D20="","Zona STOCK",IF($E20="","CEK SKU DESCRIPTION kosong","OK")))))))) | Q20: WLL-03 | R20: 2 | S20: Gantungan | T20: =IF(Q20="","",IFERROR(INDEX(DAFTAR_FIXTURE!$B$2:$B$51,MATCH(Q20,DAFTAR_FIXTURE!$A$2:$A$51,0)),"")) | U20: =IF(Q20="","",IF(T20="","CEK ID FIXTURE tidak ada di DAFTAR_FIXTURE",IF(R20="","CEK ZONA NO kosong",IF(ISNA(MATCH(T20&"|"&R20,LAYOUT!$E$2:$E$80,0)),"CEK ZONA NO di luar layout",IF(S20<>INDEX(LAYOUT!$D$2:$D$80,MATCH(T20&"|"&R20,LAYOUT!$E$2:$E$80,0)),"CEK JENIS ZONA",IF($D20="","Zona STOCK",IF($E20="","CEK SKU DESCRIPTION kosong","OK"))))))) | V20: GND-03 | W20: 1 | X20: Rak | Y20: =IF(V20="","",IFERROR(INDEX(DAFTAR_FIXTURE!$B$2:$B$51,MATCH(V20,DAFTAR_FIXTURE!$A$2:$A$51,0)),"")) | Z20: =IF(V20="","",IF(Y20="","CEK ID FIXTURE tidak ada di DAFTAR_FIXTURE",IF(W20="","CEK ZONA NO kosong",IF(ISNA(MATCH(Y20&"|"&W20,LAYOUT!$E$2:$E$80,0)),"CEK ZONA NO di luar layout",IF(X20<>INDEX(LAYOUT!$D$2:$D$80,MATCH(Y20&"|"&W20,LAYOUT!$E$2:$E$80,0)),"CEK JENIS ZONA",IF($D20="","Zona STOCK",IF($E20="","CEK SKU DESCRIPTION kosong","OK")))))))
A21: Homeware | B21: Tableware | C21: Serving Set | D21: 10681571 | E21: SERVING GLASS SQR PLATER ZEVY GOLD | G21: MAKAN | H21: A2. SERVINGWARE | I21: W/GOLD RACK GLASS | L21: WLL-03 | M21: 4 | N21: Rak | O21: =IF(L21="","",IFERROR(INDEX(DAFTAR_FIXTURE!$B$2:$B$51,MATCH(L21,DAFTAR_FIXTURE!$A$2:$A$51,0)),"")) | P21: =IF(AND($D21="",L21=""),"",IF(L21="",IF(AND(Q21="",V21=""),"Belum ditempatkan",""),IF(O21="","CEK ID FIXTURE tidak ada di DAFTAR_FIXTURE",IF(M21="","CEK ZONA NO kosong",IF(ISNA(MATCH(O21&"|"&M21,LAYOUT!$E$2:$E$80,0)),"CEK ZONA NO di luar layout",IF(N21<>INDEX(LAYOUT!$D$2:$D$80,MATCH(O21&"|"&M21,LAYOUT!$E$2:$E$80,0)),"CEK JENIS ZONA",IF($D21="","Zona STOCK",IF($E21="","CEK SKU DESCRIPTION kosong","OK")))))))) | T21: =IF(Q21="","",IFERROR(INDEX(DAFTAR_FIXTURE!$B$2:$B$51,MATCH(Q21,DAFTAR_FIXTURE!$A$2:$A$51,0)),"")) | U21: =IF(Q21="","",IF(T21="","CEK ID FIXTURE tidak ada di DAFTAR_FIXTURE",IF(R21="","CEK ZONA NO kosong",IF(ISNA(MATCH(T21&"|"&R21,LAYOUT!$E$2:$E$80,0)),"CEK ZONA NO di luar layout",IF(S21<>INDEX(LAYOUT!$D$2:$D$80,MATCH(T21&"|"&R21,LAYOUT!$E$2:$E$80,0)),"CEK JENIS ZONA",IF($D21="","Zona STOCK",IF($E21="","CEK SKU DESCRIPTION kosong","OK"))))))) | Y21: =IF(V21="","",IFERROR(INDEX(DAFTAR_FIXTURE!$B$2:$B$51,MATCH(V21,DAFTAR_FIXTURE!$A$2:$A$51,0)),"")) | Z21: =IF(V21="","",IF(Y21="","CEK ID FIXTURE tidak ada di DAFTAR_FIXTURE",IF(W21="","CEK ZONA NO kosong",IF(ISNA(MATCH(Y21&"|"&W21,LAYOUT!$E$2:$E$80,0)),"CEK ZONA NO di luar layout",IF(X21<>INDEX(LAYOUT!$D$2:$D$80,MATCH(Y21&"|"&W21,LAYOUT!$E$2:$E$80,0)),"CEK JENIS ZONA",IF($D21="","Zona STOCK",IF($E21="","CEK SKU DESCRIPTION kosong","OK")))))))
A22: Homeware | B22: Tableware | C22: Serving Set | D22: 10470029 | E22: SERVING SET W/RACK OCTAGON MARBLE (4) | G22: MAKAN | H22: A2. SERVINGWARE | I22: SERVING SET MARBLE | L22: WLL-03 | M22: 5 | N22: Rak | O22: =IF(L22="","",IFERROR(INDEX(DAFTAR_FIXTURE!$B$2:$B$51,MATCH(L22,DAFTAR_FIXTURE!$A$2:$A$51,0)),"")) | P22: =IF(AND($D22="",L22=""),"",IF(L22="",IF(AND(Q22="",V22=""),"Belum ditempatkan",""),IF(O22="","CEK ID FIXTURE tidak ada di DAFTAR_FIXTURE",IF(M22="","CEK ZONA NO kosong",IF(ISNA(MATCH(O22&"|"&M22,LAYOUT!$E$2:$E$80,0)),"CEK ZONA NO di luar layout",IF(N22<>INDEX(LAYOUT!$D$2:$D$80,MATCH(O22&"|"&M22,LAYOUT!$E$2:$E$80,0)),"CEK JENIS ZONA",IF($D22="","Zona STOCK",IF($E22="","CEK SKU DESCRIPTION kosong","OK")))))))) | T22: =IF(Q22="","",IFERROR(INDEX(DAFTAR_FIXTURE!$B$2:$B$51,MATCH(Q22,DAFTAR_FIXTURE!$A$2:$A$51,0)),"")) | U22: =IF(Q22="","",IF(T22="","CEK ID FIXTURE tidak ada di DAFTAR_FIXTURE",IF(R22="","CEK ZONA NO kosong",IF(ISNA(MATCH(T22&"|"&R22,LAYOUT!$E$2:$E$80,0)),"CEK ZONA NO di luar layout",IF(S22<>INDEX(LAYOUT!$D$2:$D$80,MATCH(T22&"|"&R22,LAYOUT!$E$2:$E$80,0)),"CEK JENIS ZONA",IF($D22="","Zona STOCK",IF($E22="","CEK SKU DESCRIPTION kosong","OK"))))))) | Y22: =IF(V22="","",IFERROR(INDEX(DAFTAR_FIXTURE!$B$2:$B$51,MATCH(V22,DAFTAR_FIXTURE!$A$2:$A$51,0)),"")) | Z22: =IF(V22="","",IF(Y22="","CEK ID FIXTURE tidak ada di DAFTAR_FIXTURE",IF(W22="","CEK ZONA NO kosong",IF(ISNA(MATCH(Y22&"|"&W22,LAYOUT!$E$2:$E$80,0)),"CEK ZONA NO di luar layout",IF(X22<>INDEX(LAYOUT!$D$2:$D$80,MATCH(Y22&"|"&W22,LAYOUT!$E$2:$E$80,0)),"CEK JENIS ZONA",IF($D22="","Zona STOCK",IF($E22="","CEK SKU DESCRIPTION kosong","OK")))))))
A23: Homeware | B23: Kitchenware | C23: Kitchen Tools | D23: 10198149 | E23: TANTA STRAINER DIA 10CM | G23: ALAT MASAK | H23: C1. KITCHEN TOOLS | I23: TANTA S/S | L23: GND-02 | M23: 1 | N23: Gantungan | O23: =IF(L23="","",IFERROR(INDEX(DAFTAR_FIXTURE!$B$2:$B$51,MATCH(L23,DAFTAR_FIXTURE!$A$2:$A$51,0)),"")) | P23: =IF(AND($D23="",L23=""),"",IF(L23="",IF(AND(Q23="",V23=""),"Belum ditempatkan",""),IF(O23="","CEK ID FIXTURE tidak ada di DAFTAR_FIXTURE",IF(M23="","CEK ZONA NO kosong",IF(ISNA(MATCH(O23&"|"&M23,LAYOUT!$E$2:$E$80,0)),"CEK ZONA NO di luar layout",IF(N23<>INDEX(LAYOUT!$D$2:$D$80,MATCH(O23&"|"&M23,LAYOUT!$E$2:$E$80,0)),"CEK JENIS ZONA",IF($D23="","Zona STOCK",IF($E23="","CEK SKU DESCRIPTION kosong","OK")))))))) | Q23: GND-02 | R23: 2 | S23: Gantungan | T23: =IF(Q23="","",IFERROR(INDEX(DAFTAR_FIXTURE!$B$2:$B$51,MATCH(Q23,DAFTAR_FIXTURE!$A$2:$A$51,0)),"")) | U23: =IF(Q23="","",IF(T23="","CEK ID FIXTURE tidak ada di DAFTAR_FIXTURE",IF(R23="","CEK ZONA NO kosong",IF(ISNA(MATCH(T23&"|"&R23,LAYOUT!$E$2:$E$80,0)),"CEK ZONA NO di luar layout",IF(S23<>INDEX(LAYOUT!$D$2:$D$80,MATCH(T23&"|"&R23,LAYOUT!$E$2:$E$80,0)),"CEK JENIS ZONA",IF($D23="","Zona STOCK",IF($E23="","CEK SKU DESCRIPTION kosong","OK"))))))) | V23: GND-02 | W23: 3 | X23: Gantungan | Y23: =IF(V23="","",IFERROR(INDEX(DAFTAR_FIXTURE!$B$2:$B$51,MATCH(V23,DAFTAR_FIXTURE!$A$2:$A$51,0)),"")) | Z23: =IF(V23="","",IF(Y23="","CEK ID FIXTURE tidak ada di DAFTAR_FIXTURE",IF(W23="","CEK ZONA NO kosong",IF(ISNA(MATCH(Y23&"|"&W23,LAYOUT!$E$2:$E$80,0)),"CEK ZONA NO di luar layout",IF(X23<>INDEX(LAYOUT!$D$2:$D$80,MATCH(Y23&"|"&W23,LAYOUT!$E$2:$E$80,0)),"CEK JENIS ZONA",IF($D23="","Zona STOCK",IF($E23="","CEK SKU DESCRIPTION kosong","OK")))))))
A24: Homeware | B24: Kitchenware | C24: Kitchen Tools | D24: 10198150 | E24: TANTA NYLON TONGS 9 INCH | G24: ALAT MASAK | H24: C1. KITCHEN TOOLS | I24: TANTA NYLON | L24: GND-02 | M24: 1 | N24: Gantungan | O24: =IF(L24="","",IFERROR(INDEX(DAFTAR_FIXTURE!$B$2:$B$51,MATCH(L24,DAFTAR_FIXTURE!$A$2:$A$51,0)),"")) | P24: =IF(AND($D24="",L24=""),"",IF(L24="",IF(AND(Q24="",V24=""),"Belum ditempatkan",""),IF(O24="","CEK ID FIXTURE tidak ada di DAFTAR_FIXTURE",IF(M24="","CEK ZONA NO kosong",IF(ISNA(MATCH(O24&"|"&M24,LAYOUT!$E$2:$E$80,0)),"CEK ZONA NO di luar layout",IF(N24<>INDEX(LAYOUT!$D$2:$D$80,MATCH(O24&"|"&M24,LAYOUT!$E$2:$E$80,0)),"CEK JENIS ZONA",IF($D24="","Zona STOCK",IF($E24="","CEK SKU DESCRIPTION kosong","OK")))))))) | Q24: GND-02 | R24: 2 | S24: Gantungan | T24: =IF(Q24="","",IFERROR(INDEX(DAFTAR_FIXTURE!$B$2:$B$51,MATCH(Q24,DAFTAR_FIXTURE!$A$2:$A$51,0)),"")) | U24: =IF(Q24="","",IF(T24="","CEK ID FIXTURE tidak ada di DAFTAR_FIXTURE",IF(R24="","CEK ZONA NO kosong",IF(ISNA(MATCH(T24&"|"&R24,LAYOUT!$E$2:$E$80,0)),"CEK ZONA NO di luar layout",IF(S24<>INDEX(LAYOUT!$D$2:$D$80,MATCH(T24&"|"&R24,LAYOUT!$E$2:$E$80,0)),"CEK JENIS ZONA",IF($D24="","Zona STOCK",IF($E24="","CEK SKU DESCRIPTION kosong","OK"))))))) | V24: GND-02 | W24: 3 | X24: Gantungan | Y24: =IF(V24="","",IFERROR(INDEX(DAFTAR_FIXTURE!$B$2:$B$51,MATCH(V24,DAFTAR_FIXTURE!$A$2:$A$51,0)),"")) | Z24: =IF(V24="","",IF(Y24="","CEK ID FIXTURE tidak ada di DAFTAR_FIXTURE",IF(W24="","CEK ZONA NO kosong",IF(ISNA(MATCH(Y24&"|"&W24,LAYOUT!$E$2:$E$80,0)),"CEK ZONA NO di luar layout",IF(X24<>INDEX(LAYOUT!$D$2:$D$80,MATCH(Y24&"|"&W24,LAYOUT!$E$2:$E$80,0)),"CEK JENIS ZONA",IF($D24="","Zona STOCK",IF($E24="","CEK SKU DESCRIPTION kosong","OK")))))))
A25: Homeware | B25: Kitchenware | C25: Kitchen Tools | D25: 10198151 | E25: TANTA NYLON TONGS 12 INCH | G25: ALAT MASAK | H25: C1. KITCHEN TOOLS | I25: TANTA NYLON | L25: GND-02 | M25: 1 | N25: Gantungan | O25: =IF(L25="","",IFERROR(INDEX(DAFTAR_FIXTURE!$B$2:$B$51,MATCH(L25,DAFTAR_FIXTURE!$A$2:$A$51,0)),"")) | P25: =IF(AND($D25="",L25=""),"",IF(L25="",IF(AND(Q25="",V25=""),"Belum ditempatkan",""),IF(O25="","CEK ID FIXTURE tidak ada di DAFTAR_FIXTURE",IF(M25="","CEK ZONA NO kosong",IF(ISNA(MATCH(O25&"|"&M25,LAYOUT!$E$2:$E$80,0)),"CEK ZONA NO di luar layout",IF(N25<>INDEX(LAYOUT!$D$2:$D$80,MATCH(O25&"|"&M25,LAYOUT!$E$2:$E$80,0)),"CEK JENIS ZONA",IF($D25="","Zona STOCK",IF($E25="","CEK SKU DESCRIPTION kosong","OK")))))))) | Q25: GND-02 | R25: 2 | S25: Gantungan | T25: =IF(Q25="","",IFERROR(INDEX(DAFTAR_FIXTURE!$B$2:$B$51,MATCH(Q25,DAFTAR_FIXTURE!$A$2:$A$51,0)),"")) | U25: =IF(Q25="","",IF(T25="","CEK ID FIXTURE tidak ada di DAFTAR_FIXTURE",IF(R25="","CEK ZONA NO kosong",IF(ISNA(MATCH(T25&"|"&R25,LAYOUT!$E$2:$E$80,0)),"CEK ZONA NO di luar layout",IF(S25<>INDEX(LAYOUT!$D$2:$D$80,MATCH(T25&"|"&R25,LAYOUT!$E$2:$E$80,0)),"CEK JENIS ZONA",IF($D25="","Zona STOCK",IF($E25="","CEK SKU DESCRIPTION kosong","OK"))))))) | V25: GND-02 | W25: 3 | X25: Gantungan | Y25: =IF(V25="","",IFERROR(INDEX(DAFTAR_FIXTURE!$B$2:$B$51,MATCH(V25,DAFTAR_FIXTURE!$A$2:$A$51,0)),"")) | Z25: =IF(V25="","",IF(Y25="","CEK ID FIXTURE tidak ada di DAFTAR_FIXTURE",IF(W25="","CEK ZONA NO kosong",IF(ISNA(MATCH(Y25&"|"&W25,LAYOUT!$E$2:$E$80,0)),"CEK ZONA NO di luar layout",IF(X25<>INDEX(LAYOUT!$D$2:$D$80,MATCH(Y25&"|"&W25,LAYOUT!$E$2:$E$80,0)),"CEK JENIS ZONA",IF($D25="","Zona STOCK",IF($E25="","CEK SKU DESCRIPTION kosong","OK")))))))
A26: Homeware | B26: Kitchenware | C26: Kitchen Tools | D26: 10198152 | E26: TANTA S/S SOLID TURNER M | G26: ALAT MASAK | H26: C1. KITCHEN TOOLS | I26: TANTA S/S | L26: GND-02 | M26: 1 | N26: Gantungan | O26: =IF(L26="","",IFERROR(INDEX(DAFTAR_FIXTURE!$B$2:$B$51,MATCH(L26,DAFTAR_FIXTURE!$A$2:$A$51,0)),"")) | P26: =IF(AND($D26="",L26=""),"",IF(L26="",IF(AND(Q26="",V26=""),"Belum ditempatkan",""),IF(O26="","CEK ID FIXTURE tidak ada di DAFTAR_FIXTURE",IF(M26="","CEK ZONA NO kosong",IF(ISNA(MATCH(O26&"|"&M26,LAYOUT!$E$2:$E$80,0)),"CEK ZONA NO di luar layout",IF(N26<>INDEX(LAYOUT!$D$2:$D$80,MATCH(O26&"|"&M26,LAYOUT!$E$2:$E$80,0)),"CEK JENIS ZONA",IF($D26="","Zona STOCK",IF($E26="","CEK SKU DESCRIPTION kosong","OK")))))))) | Q26: GND-02 | R26: 2 | S26: Gantungan | T26: =IF(Q26="","",IFERROR(INDEX(DAFTAR_FIXTURE!$B$2:$B$51,MATCH(Q26,DAFTAR_FIXTURE!$A$2:$A$51,0)),"")) | U26: =IF(Q26="","",IF(T26="","CEK ID FIXTURE tidak ada di DAFTAR_FIXTURE",IF(R26="","CEK ZONA NO kosong",IF(ISNA(MATCH(T26&"|"&R26,LAYOUT!$E$2:$E$80,0)),"CEK ZONA NO di luar layout",IF(S26<>INDEX(LAYOUT!$D$2:$D$80,MATCH(T26&"|"&R26,LAYOUT!$E$2:$E$80,0)),"CEK JENIS ZONA",IF($D26="","Zona STOCK",IF($E26="","CEK SKU DESCRIPTION kosong","OK"))))))) | V26: GND-02 | W26: 3 | X26: Gantungan | Y26: =IF(V26="","",IFERROR(INDEX(DAFTAR_FIXTURE!$B$2:$B$51,MATCH(V26,DAFTAR_FIXTURE!$A$2:$A$51,0)),"")) | Z26: =IF(V26="","",IF(Y26="","CEK ID FIXTURE tidak ada di DAFTAR_FIXTURE",IF(W26="","CEK ZONA NO kosong",IF(ISNA(MATCH(Y26&"|"&W26,LAYOUT!$E$2:$E$80,0)),"CEK ZONA NO di luar layout",IF(X26<>INDEX(LAYOUT!$D$2:$D$80,MATCH(Y26&"|"&W26,LAYOUT!$E$2:$E$80,0)),"CEK JENIS ZONA",IF($D26="","Zona STOCK",IF($E26="","CEK SKU DESCRIPTION kosong","OK")))))))
A27: Homeware | B27: Kitchenware | C27: Kitchen Tools | D27: 10198154 | E27: TANTA S/S LADLE | G27: ALAT MASAK | H27: C1. KITCHEN TOOLS | I27: TANTA S/S | L27: GND-02 | M27: 1 | N27: Gantungan | O27: =IF(L27="","",IFERROR(INDEX(DAFTAR_FIXTURE!$B$2:$B$51,MATCH(L27,DAFTAR_FIXTURE!$A$2:$A$51,0)),"")) | P27: =IF(AND($D27="",L27=""),"",IF(L27="",IF(AND(Q27="",V27=""),"Belum ditempatkan",""),IF(O27="","CEK ID FIXTURE tidak ada di DAFTAR_FIXTURE",IF(M27="","CEK ZONA NO kosong",IF(ISNA(MATCH(O27&"|"&M27,LAYOUT!$E$2:$E$80,0)),"CEK ZONA NO di luar layout",IF(N27<>INDEX(LAYOUT!$D$2:$D$80,MATCH(O27&"|"&M27,LAYOUT!$E$2:$E$80,0)),"CEK JENIS ZONA",IF($D27="","Zona STOCK",IF($E27="","CEK SKU DESCRIPTION kosong","OK")))))))) | Q27: GND-02 | R27: 2 | S27: Gantungan | T27: =IF(Q27="","",IFERROR(INDEX(DAFTAR_FIXTURE!$B$2:$B$51,MATCH(Q27,DAFTAR_FIXTURE!$A$2:$A$51,0)),"")) | U27: =IF(Q27="","",IF(T27="","CEK ID FIXTURE tidak ada di DAFTAR_FIXTURE",IF(R27="","CEK ZONA NO kosong",IF(ISNA(MATCH(T27&"|"&R27,LAYOUT!$E$2:$E$80,0)),"CEK ZONA NO di luar layout",IF(S27<>INDEX(LAYOUT!$D$2:$D$80,MATCH(T27&"|"&R27,LAYOUT!$E$2:$E$80,0)),"CEK JENIS ZONA",IF($D27="","Zona STOCK",IF($E27="","CEK SKU DESCRIPTION kosong","OK"))))))) | V27: GND-02 | W27: 3 | X27: Gantungan | Y27: =IF(V27="","",IFERROR(INDEX(DAFTAR_FIXTURE!$B$2:$B$51,MATCH(V27,DAFTAR_FIXTURE!$A$2:$A$51,0)),"")) | Z27: =IF(V27="","",IF(Y27="","CEK ID FIXTURE tidak ada di DAFTAR_FIXTURE",IF(W27="","CEK ZONA NO kosong",IF(ISNA(MATCH(Y27&"|"&W27,LAYOUT!$E$2:$E$80,0)),"CEK ZONA NO di luar layout",IF(X27<>INDEX(LAYOUT!$D$2:$D$80,MATCH(Y27&"|"&W27,LAYOUT!$E$2:$E$80,0)),"CEK JENIS ZONA",IF($D27="","Zona STOCK",IF($E27="","CEK SKU DESCRIPTION kosong","OK")))))))
A28: Homeware | B28: Kitchenware | C28: Kitchen Tools | D28: 10198156 | E28: TANTA NYLON SLOTTED TURNER M | G28: ALAT MASAK | H28: C1. KITCHEN TOOLS | I28: TANTA NYLON | L28: GND-02 | M28: 1 | N28: Gantungan | O28: =IF(L28="","",IFERROR(INDEX(DAFTAR_FIXTURE!$B$2:$B$51,MATCH(L28,DAFTAR_FIXTURE!$A$2:$A$51,0)),"")) | P28: =IF(AND($D28="",L28=""),"",IF(L28="",IF(AND(Q28="",V28=""),"Belum ditempatkan",""),IF(O28="","CEK ID FIXTURE tidak ada di DAFTAR_FIXTURE",IF(M28="","CEK ZONA NO kosong",IF(ISNA(MATCH(O28&"|"&M28,LAYOUT!$E$2:$E$80,0)),"CEK ZONA NO di luar layout",IF(N28<>INDEX(LAYOUT!$D$2:$D$80,MATCH(O28&"|"&M28,LAYOUT!$E$2:$E$80,0)),"CEK JENIS ZONA",IF($D28="","Zona STOCK",IF($E28="","CEK SKU DESCRIPTION kosong","OK")))))))) | Q28: GND-02 | R28: 2 | S28: Gantungan | T28: =IF(Q28="","",IFERROR(INDEX(DAFTAR_FIXTURE!$B$2:$B$51,MATCH(Q28,DAFTAR_FIXTURE!$A$2:$A$51,0)),"")) | U28: =IF(Q28="","",IF(T28="","CEK ID FIXTURE tidak ada di DAFTAR_FIXTURE",IF(R28="","CEK ZONA NO kosong",IF(ISNA(MATCH(T28&"|"&R28,LAYOUT!$E$2:$E$80,0)),"CEK ZONA NO di luar layout",IF(S28<>INDEX(LAYOUT!$D$2:$D$80,MATCH(T28&"|"&R28,LAYOUT!$E$2:$E$80,0)),"CEK JENIS ZONA",IF($D28="","Zona STOCK",IF($E28="","CEK SKU DESCRIPTION kosong","OK"))))))) | V28: GND-02 | W28: 3 | X28: Gantungan | Y28: =IF(V28="","",IFERROR(INDEX(DAFTAR_FIXTURE!$B$2:$B$51,MATCH(V28,DAFTAR_FIXTURE!$A$2:$A$51,0)),"")) | Z28: =IF(V28="","",IF(Y28="","CEK ID FIXTURE tidak ada di DAFTAR_FIXTURE",IF(W28="","CEK ZONA NO kosong",IF(ISNA(MATCH(Y28&"|"&W28,LAYOUT!$E$2:$E$80,0)),"CEK ZONA NO di luar layout",IF(X28<>INDEX(LAYOUT!$D$2:$D$80,MATCH(Y28&"|"&W28,LAYOUT!$E$2:$E$80,0)),"CEK JENIS ZONA",IF($D28="","Zona STOCK",IF($E28="","CEK SKU DESCRIPTION kosong","OK")))))))
A29: Homeware | B29: Kitchenware | C29: Kitchen Tools | D29: 10198157 | E29: TANTA NYLON SOLID TURNER L | G29: ALAT MASAK | H29: C1. KITCHEN TOOLS | I29: TANTA NYLON | L29: GND-02 | M29: 1 | N29: Gantungan | O29: =IF(L29="","",IFERROR(INDEX(DAFTAR_FIXTURE!$B$2:$B$51,MATCH(L29,DAFTAR_FIXTURE!$A$2:$A$51,0)),"")) | P29: =IF(AND($D29="",L29=""),"",IF(L29="",IF(AND(Q29="",V29=""),"Belum ditempatkan",""),IF(O29="","CEK ID FIXTURE tidak ada di DAFTAR_FIXTURE",IF(M29="","CEK ZONA NO kosong",IF(ISNA(MATCH(O29&"|"&M29,LAYOUT!$E$2:$E$80,0)),"CEK ZONA NO di luar layout",IF(N29<>INDEX(LAYOUT!$D$2:$D$80,MATCH(O29&"|"&M29,LAYOUT!$E$2:$E$80,0)),"CEK JENIS ZONA",IF($D29="","Zona STOCK",IF($E29="","CEK SKU DESCRIPTION kosong","OK")))))))) | Q29: GND-02 | R29: 2 | S29: Gantungan | T29: =IF(Q29="","",IFERROR(INDEX(DAFTAR_FIXTURE!$B$2:$B$51,MATCH(Q29,DAFTAR_FIXTURE!$A$2:$A$51,0)),"")) | U29: =IF(Q29="","",IF(T29="","CEK ID FIXTURE tidak ada di DAFTAR_FIXTURE",IF(R29="","CEK ZONA NO kosong",IF(ISNA(MATCH(T29&"|"&R29,LAYOUT!$E$2:$E$80,0)),"CEK ZONA NO di luar layout",IF(S29<>INDEX(LAYOUT!$D$2:$D$80,MATCH(T29&"|"&R29,LAYOUT!$E$2:$E$80,0)),"CEK JENIS ZONA",IF($D29="","Zona STOCK",IF($E29="","CEK SKU DESCRIPTION kosong","OK"))))))) | V29: GND-02 | W29: 3 | X29: Gantungan | Y29: =IF(V29="","",IFERROR(INDEX(DAFTAR_FIXTURE!$B$2:$B$51,MATCH(V29,DAFTAR_FIXTURE!$A$2:$A$51,0)),"")) | Z29: =IF(V29="","",IF(Y29="","CEK ID FIXTURE tidak ada di DAFTAR_FIXTURE",IF(W29="","CEK ZONA NO kosong",IF(ISNA(MATCH(Y29&"|"&W29,LAYOUT!$E$2:$E$80,0)),"CEK ZONA NO di luar layout",IF(X29<>INDEX(LAYOUT!$D$2:$D$80,MATCH(Y29&"|"&W29,LAYOUT!$E$2:$E$80,0)),"CEK JENIS ZONA",IF($D29="","Zona STOCK",IF($E29="","CEK SKU DESCRIPTION kosong","OK")))))))
A30: Homeware | B30: Kitchenware | C30: Kitchen Tools | D30: 10198159 | E30: TANTA NYLON LADLE | G30: ALAT MASAK | H30: C1. KITCHEN TOOLS | I30: TANTA NYLON | L30: GND-02 | M30: 1 | N30: Gantungan | O30: =IF(L30="","",IFERROR(INDEX(DAFTAR_FIXTURE!$B$2:$B$51,MATCH(L30,DAFTAR_FIXTURE!$A$2:$A$51,0)),"")) | P30: =IF(AND($D30="",L30=""),"",IF(L30="",IF(AND(Q30="",V30=""),"Belum ditempatkan",""),IF(O30="","CEK ID FIXTURE tidak ada di DAFTAR_FIXTURE",IF(M30="","CEK ZONA NO kosong",IF(ISNA(MATCH(O30&"|"&M30,LAYOUT!$E$2:$E$80,0)),"CEK ZONA NO di luar layout",IF(N30<>INDEX(LAYOUT!$D$2:$D$80,MATCH(O30&"|"&M30,LAYOUT!$E$2:$E$80,0)),"CEK JENIS ZONA",IF($D30="","Zona STOCK",IF($E30="","CEK SKU DESCRIPTION kosong","OK")))))))) | Q30: GND-02 | R30: 2 | S30: Gantungan | T30: =IF(Q30="","",IFERROR(INDEX(DAFTAR_FIXTURE!$B$2:$B$51,MATCH(Q30,DAFTAR_FIXTURE!$A$2:$A$51,0)),"")) | U30: =IF(Q30="","",IF(T30="","CEK ID FIXTURE tidak ada di DAFTAR_FIXTURE",IF(R30="","CEK ZONA NO kosong",IF(ISNA(MATCH(T30&"|"&R30,LAYOUT!$E$2:$E$80,0)),"CEK ZONA NO di luar layout",IF(S30<>INDEX(LAYOUT!$D$2:$D$80,MATCH(T30&"|"&R30,LAYOUT!$E$2:$E$80,0)),"CEK JENIS ZONA",IF($D30="","Zona STOCK",IF($E30="","CEK SKU DESCRIPTION kosong","OK"))))))) | V30: GND-02 | W30: 3 | X30: Gantungan | Y30: =IF(V30="","",IFERROR(INDEX(DAFTAR_FIXTURE!$B$2:$B$51,MATCH(V30,DAFTAR_FIXTURE!$A$2:$A$51,0)),"")) | Z30: =IF(V30="","",IF(Y30="","CEK ID FIXTURE tidak ada di DAFTAR_FIXTURE",IF(W30="","CEK ZONA NO kosong",IF(ISNA(MATCH(Y30&"|"&W30,LAYOUT!$E$2:$E$80,0)),"CEK ZONA NO di luar layout",IF(X30<>INDEX(LAYOUT!$D$2:$D$80,MATCH(Y30&"|"&W30,LAYOUT!$E$2:$E$80,0)),"CEK JENIS ZONA",IF($D30="","Zona STOCK",IF($E30="","CEK SKU DESCRIPTION kosong","OK")))))))
A31: Homeware | B31: Kitchenware | C31: Kitchen Tools | D31: 10198160 | E31: TANTA NYLON WHISK | G31: ALAT MASAK | H31: C1. KITCHEN TOOLS | I31: TANTA NYLON | L31: GND-02 | M31: 1 | N31: Gantungan | O31: =IF(L31="","",IFERROR(INDEX(DAFTAR_FIXTURE!$B$2:$B$51,MATCH(L31,DAFTAR_FIXTURE!$A$2:$A$51,0)),"")) | P31: =IF(AND($D31="",L31=""),"",IF(L31="",IF(AND(Q31="",V31=""),"Belum ditempatkan",""),IF(O31="","CEK ID FIXTURE tidak ada di DAFTAR_FIXTURE",IF(M31="","CEK ZONA NO kosong",IF(ISNA(MATCH(O31&"|"&M31,LAYOUT!$E$2:$E$80,0)),"CEK ZONA NO di luar layout",IF(N31<>INDEX(LAYOUT!$D$2:$D$80,MATCH(O31&"|"&M31,LAYOUT!$E$2:$E$80,0)),"CEK JENIS ZONA",IF($D31="","Zona STOCK",IF($E31="","CEK SKU DESCRIPTION kosong","OK")))))))) | Q31: GND-02 | R31: 2 | S31: Gantungan | T31: =IF(Q31="","",IFERROR(INDEX(DAFTAR_FIXTURE!$B$2:$B$51,MATCH(Q31,DAFTAR_FIXTURE!$A$2:$A$51,0)),"")) | U31: =IF(Q31="","",IF(T31="","CEK ID FIXTURE tidak ada di DAFTAR_FIXTURE",IF(R31="","CEK ZONA NO kosong",IF(ISNA(MATCH(T31&"|"&R31,LAYOUT!$E$2:$E$80,0)),"CEK ZONA NO di luar layout",IF(S31<>INDEX(LAYOUT!$D$2:$D$80,MATCH(T31&"|"&R31,LAYOUT!$E$2:$E$80,0)),"CEK JENIS ZONA",IF($D31="","Zona STOCK",IF($E31="","CEK SKU DESCRIPTION kosong","OK"))))))) | V31: GND-02 | W31: 3 | X31: Gantungan | Y31: =IF(V31="","",IFERROR(INDEX(DAFTAR_FIXTURE!$B$2:$B$51,MATCH(V31,DAFTAR_FIXTURE!$A$2:$A$51,0)),"")) | Z31: =IF(V31="","",IF(Y31="","CEK ID FIXTURE tidak ada di DAFTAR_FIXTURE",IF(W31="","CEK ZONA NO kosong",IF(ISNA(MATCH(Y31&"|"&W31,LAYOUT!$E$2:$E$80,0)),"CEK ZONA NO di luar layout",IF(X31<>INDEX(LAYOUT!$D$2:$D$80,MATCH(Y31&"|"&W31,LAYOUT!$E$2:$E$80,0)),"CEK JENIS ZONA",IF($D31="","Zona STOCK",IF($E31="","CEK SKU DESCRIPTION kosong","OK")))))))
A32: Homeware | B32: Kitchenware | C32: Kitchen Tools | D32: 10198149 | E32: TANTA STRAINER DIA 10CM | G32: ALAT MASAK | H32: C1. KITCHEN TOOLS | I32: TANTA S/S | L32: GND-02 | M32: 4 | N32: Gantungan | O32: =IF(L32="","",IFERROR(INDEX(DAFTAR_FIXTURE!$B$2:$B$51,MATCH(L32,DAFTAR_FIXTURE!$A$2:$A$51,0)),"")) | P32: =IF(AND($D32="",L32=""),"",IF(L32="",IF(AND(Q32="",V32=""),"Belum ditempatkan",""),IF(O32="","CEK ID FIXTURE tidak ada di DAFTAR_FIXTURE",IF(M32="","CEK ZONA NO kosong",IF(ISNA(MATCH(O32&"|"&M32,LAYOUT!$E$2:$E$80,0)),"CEK ZONA NO di luar layout",IF(N32<>INDEX(LAYOUT!$D$2:$D$80,MATCH(O32&"|"&M32,LAYOUT!$E$2:$E$80,0)),"CEK JENIS ZONA",IF($D32="","Zona STOCK",IF($E32="","CEK SKU DESCRIPTION kosong","OK")))))))) | Q32: GND-02 | R32: 2 | S32: Gantungan | T32: =IF(Q32="","",IFERROR(INDEX(DAFTAR_FIXTURE!$B$2:$B$51,MATCH(Q32,DAFTAR_FIXTURE!$A$2:$A$51,0)),"")) | U32: =IF(Q32="","",IF(T32="","CEK ID FIXTURE tidak ada di DAFTAR_FIXTURE",IF(R32="","CEK ZONA NO kosong",IF(ISNA(MATCH(T32&"|"&R32,LAYOUT!$E$2:$E$80,0)),"CEK ZONA NO di luar layout",IF(S32<>INDEX(LAYOUT!$D$2:$D$80,MATCH(T32&"|"&R32,LAYOUT!$E$2:$E$80,0)),"CEK JENIS ZONA",IF($D32="","Zona STOCK",IF($E32="","CEK SKU DESCRIPTION kosong","OK"))))))) | V32: GND-02 | W32: 3 | X32: Gantungan | Y32: =IF(V32="","",IFERROR(INDEX(DAFTAR_FIXTURE!$B$2:$B$51,MATCH(V32,DAFTAR_FIXTURE!$A$2:$A$51,0)),"")) | Z32: =IF(V32="","",IF(Y32="","CEK ID FIXTURE tidak ada di DAFTAR_FIXTURE",IF(W32="","CEK ZONA NO kosong",IF(ISNA(MATCH(Y32&"|"&W32,LAYOUT!$E$2:$E$80,0)),"CEK ZONA NO di luar layout",IF(X32<>INDEX(LAYOUT!$D$2:$D$80,MATCH(Y32&"|"&W32,LAYOUT!$E$2:$E$80,0)),"CEK JENIS ZONA",IF($D32="","Zona STOCK",IF($E32="","CEK SKU DESCRIPTION kosong","OK")))))))
A33: Homeware | B33: Kitchenware | C33: Kitchen Tools | D33: 10198150 | E33: TANTA NYLON TONGS 9 INCH | G33: ALAT MASAK | H33: C1. KITCHEN TOOLS | I33: TANTA NYLON | L33: GND-02 | M33: 4 | N33: Gantungan | O33: =IF(L33="","",IFERROR(INDEX(DAFTAR_FIXTURE!$B$2:$B$51,MATCH(L33,DAFTAR_FIXTURE!$A$2:$A$51,0)),"")) | P33: =IF(AND($D33="",L33=""),"",IF(L33="",IF(AND(Q33="",V33=""),"Belum ditempatkan",""),IF(O33="","CEK ID FIXTURE tidak ada di DAFTAR_FIXTURE",IF(M33="","CEK ZONA NO kosong",IF(ISNA(MATCH(O33&"|"&M33,LAYOUT!$E$2:$E$80,0)),"CEK ZONA NO di luar layout",IF(N33<>INDEX(LAYOUT!$D$2:$D$80,MATCH(O33&"|"&M33,LAYOUT!$E$2:$E$80,0)),"CEK JENIS ZONA",IF($D33="","Zona STOCK",IF($E33="","CEK SKU DESCRIPTION kosong","OK")))))))) | Q33: GND-02 | R33: 2 | S33: Gantungan | T33: =IF(Q33="","",IFERROR(INDEX(DAFTAR_FIXTURE!$B$2:$B$51,MATCH(Q33,DAFTAR_FIXTURE!$A$2:$A$51,0)),"")) | U33: =IF(Q33="","",IF(T33="","CEK ID FIXTURE tidak ada di DAFTAR_FIXTURE",IF(R33="","CEK ZONA NO kosong",IF(ISNA(MATCH(T33&"|"&R33,LAYOUT!$E$2:$E$80,0)),"CEK ZONA NO di luar layout",IF(S33<>INDEX(LAYOUT!$D$2:$D$80,MATCH(T33&"|"&R33,LAYOUT!$E$2:$E$80,0)),"CEK JENIS ZONA",IF($D33="","Zona STOCK",IF($E33="","CEK SKU DESCRIPTION kosong","OK"))))))) | V33: GND-02 | W33: 3 | X33: Gantungan | Y33: =IF(V33="","",IFERROR(INDEX(DAFTAR_FIXTURE!$B$2:$B$51,MATCH(V33,DAFTAR_FIXTURE!$A$2:$A$51,0)),"")) | Z33: =IF(V33="","",IF(Y33="","CEK ID FIXTURE tidak ada di DAFTAR_FIXTURE",IF(W33="","CEK ZONA NO kosong",IF(ISNA(MATCH(Y33&"|"&W33,LAYOUT!$E$2:$E$80,0)),"CEK ZONA NO di luar layout",IF(X33<>INDEX(LAYOUT!$D$2:$D$80,MATCH(Y33&"|"&W33,LAYOUT!$E$2:$E$80,0)),"CEK JENIS ZONA",IF($D33="","Zona STOCK",IF($E33="","CEK SKU DESCRIPTION kosong","OK")))))))
