Workbook
Name FIXTURE_IDS: OFFSET(DAFTAR_FIXTURE!$A$2,0,0,MAX(1,COUNTA(DAFTAR_FIXTURE!$A$2:$A$51)),1)

Sheet PETUNJUK
A1: TEMPLATE DATA PLANOGRAM
A2: Isi sheet DATA dari kiri ke kanan. Satu baris = satu SKU. Kolom A–K = template wajib internal. Kolom L ke kanan = penempatan fixture khusus untuk HTML planogram.
A4: LANGKAH 1 — TEMPLATE WAJIB INTERNAL (kolom A–K)
A5: DEPT, COMM, CLASS | B5: Hirarki produk dari data master. Dipakai sebagai filter di aplikasi.
A6: SKU * | B6: Kode artikel. Wajib. Dipakai juga untuk membentuk link gambar.
A7: SKU DESCRIPTION * | B7: Nama item. Wajib. Tampil di kartu produk.
A8: STOCK | B8: Informasi stok SKU (dari data master).
A9: GRUP DISPLAY | B9: Contoh: PENYIMPANAN, MAKAN, MASAK. Dipakai sebagai filter. Isi "X" dianggap kosong.
A10: GRUP ADJACENCY | B10: Contoh: E4. CANISTER, A2. SERVINGWARE. Dipakai sebagai filter.
A11: SERIES / SUB SERIES | B11: Contoh: GLASS FANCY, POLLA. Dipakai sebagai filter.
A12: LINK IMAGE | B12: Opsional. Kosong = otomatis: https://cdn.ruparupa.io/fit-in/850x850/ruparupa-com/image/upload/Products/[SKU]_1.jpg
A14: LANGKAH 2 — PENEMPATAN KE FIXTURE, SAMPAI 3 FIXTURE PER SKU (header hijau)
A15: FIXTURE 1 (kolom L–N) | B15: ID FIXTURE 1 (dropdown dari sheet DAFTAR_FIXTURE), ZONA NO 1 (dari atas, mulai 1; lihat sheet LAYOUT), JENIS ZONA 1 (Shelving / Gantungan).
A16: FIXTURE 2 (kolom Q–S) | B16: Isi jika SKU yang sama juga ditampilkan di fixture lain (mis. Wall dan Gondola). Kosongkan jika tidak dipakai.
A17: FIXTURE 3 (kolom V–X) | B17: Cadangan untuk fixture ketiga. Kosongkan jika tidak dipakai.
A19: LANGKAH 3 — OTOMATIS (header abu-abu, jangan diisi / dihapus)
A20: JENIS FIXTURE 1 / 2 / 3 | B20: Dibaca dari ID FIXTURE (sheet DAFTAR_FIXTURE).
A21: STATUS 1 / 2 / 3 | B21: OK / Zona STOCK / Belum ditempatkan / CEK + penyebab. Semua penempatan harus OK sebelum diimpor.
A23: ATURAN PENEMPATAN
A24: 1. Satu baris = satu SKU. SKU yang sama tidak perlu ditulis lagi untuk fixture kedua / ketiga: isi kolom Fixture 2 / Fixture 3 pada baris yang sama.
A25: 2. Jika satu SKU perlu lebih dari 3 penempatan (mis. di banyak zona), tulis SKU itu lagi di baris baru.
A26: 3. Urutan item dari kiri ke kanan dalam satu zona mengikuti urutan baris di Excel (baris atas lebih dulu).
A27: 4. Jumlah item yang tampil = jumlah penempatan. Tidak ada facing, susun, ukuran, brand, atau prioritas.
A28: 5. Zona yang tidak berisi item (baris ID FIXTURE 1 + ZONA NO 1 tanpa SKU, atau zona yang tidak ditulis sama sekali) dianggap tempat STOCK dan ditulis STOCK di planogram.
A29: 6. Baris yang hanya berisi data SKU (tanpa ID FIXTURE) = masuk daftar SKU saja, belum ditempatkan.
A30: 7. Isi GRUP DISPLAY, GRUP ADJACENCY, SERIES dengan ejaan konsisten agar pilihan filter di aplikasi tidak terpecah.
A31: Buka dulu di Excel lalu simpan agar kolom otomatis terhitung sebelum diimpor.
A33: SHEET DIMENSI (OPSIONAL) — ukuran kemasan untuk menghitung muat berapa pcs
A34: Kapan dipakai | B34: Hanya jika sheet DIMENSI berisi data DAN pengguna meminta di aplikasi. Kosong = aplikasi berjalan seperti biasa.
A35: SKU * | B35: Harus sama dengan kolom SKU di sheet DATA. Satu SKU satu baris.
A36: LEBAR / TINGGI / KEDALAMAN (cm) * | B36: Ukuran kemasan saat dipajang. LEBAR = sisi yang menghadap depan (kiri-kanan); TINGGI = atas-bawah; KEDALAMAN = depan-belakang. Untuk kemasan gantung, kedalaman = tebal kemasan.
A37: FACING | B37: Jumlah deretan produk berdampingan di depan. Kosong = 1.
A38: MAKS SUSUN | B38: Boleh ditumpuk berapa tingkat. Kosong atau 1 = tidak ditumpuk.
A39: BOLEH DIPUTAR | B39: Ya = lebar dan kedalaman boleh ditukar bila itu membuat lebih banyak yang muat. Kosong = Tidak.
A40: Kolom otomatis | B40: Deskripsi, estimasi pcs per facing (gambaran cepat rak Gondola), dan STATUS. Jangan diisi atau dihapus.
A42: SAMBUNGAN (OPSIONAL) — kolom SAMBUNGAN dan URUTAN SAMBUNG di tiap fixture (1, 2, 3)
A43: Fungsi | B43: Menyimpan urutan fixture yang tampil menempel (Sambung visual). Muncul sebagai pilihan "Template sambungan dari Excel". Kosong = tidak ada template.
A44: Cara isi | B44: Di baris SKU yang sudah memiliki ID FIXTURE, isi SAMBUNGAN dan URUTAN SAMBUNG di blok fixture yang sama. Cukup di satu baris per fixture (baris mana saja milik fixture itu).
A45: SAMBUNGAN | B45: Nama rangkaian, bebas (mis. WALL-RUN-1). Fixture dengan nama sama = satu rangkaian. Satu rangkaian satu kategori (Wall, Gondola, atau Pallet). Endcap tidak ikut sambung.
A46: URUTAN SAMBUNG | B46: Nomor urut fixture dari kiri ke kanan, mulai 1. Wajib diisi bila SAMBUNGAN diisi.
...

Sheet DATA
A1: DEPT | B1: COMM | C1: CLASS | D1: SKU | E1: SKU DESCRIPTION | F1: STOCK | G1: GRUP DISPLAY | H1: GRUP ADJACENCY | I1: SERIES | J1: SUB SERIES* | K1: LINK IMAGE (opsional) | L1: ID FIXTURE 1 | M1: ZONA NO 1 | N1: JENIS ZONA 1 | O1: SAMBUNGAN 1 | P1: URUTAN SAMBUNG 1 | Q1: URUTAN DISPLAY 1 | R1: JENIS FIXTURE 1 (otomatis) | S1: STATUS 1 (otomatis) | T1: ID FIXTURE 2 | U1: ZONA NO 2 | V1: JENIS ZONA 2 | W1: SAMBUNGAN 2 | X1: URUTAN SAMBUNG 2 | Y1: URUTAN DISPLAY 2 | Z1: JENIS FIXTURE 2 (otomatis) | AA1: STATUS 2 (otomatis) | AB1: ID FIXTURE 3 | AC1: ZONA NO 3 | AD1: JENIS ZONA 3 | AE1: SAMBUNGAN 3 | AF1: URUTAN SAMBUNG 3 | AG1: URUTAN DISPLAY 3 | AH1: JENIS FIXTURE 3 (otomatis) | AI1: STATUS 3 (otomatis)
A2: Homeware | B2: Storage | C2: Food Storage | D2: 10680419 | E2: MOSQUE DOME GLASS JAR SET OF 3 450ML | G2: PENYIMPANAN | H2: E4. CANISTER | I2: GLASS FANCY | L2: GDN 4S | M2: 1 | N2: Shelving | O2: GONDOLA-RUN-1 | P2: 1 | R2: =IF(L2="","",IFERROR(INDEX(DAFTAR_FIXTURE!$B$2:$B$51,MATCH(L2,DAFTAR_FIXTURE!$A$2:$A$51,0)),"")) | S2: =IF(AND($D2="",L2=""),"",IF(L2="",IF(AND(T2="",AB2=""),"Belum ditempatkan",""),IF(R2="","CEK ID FIXTURE tidak ada di DAFTAR_FIXTURE",IF(M2="","CEK ZONA NO kosong",IF(ISNA(MATCH(R2&"|"&M2,LAYOUT!$E$2:$E$80,0)),"CEK ZONA NO di luar layout",IF(N2<>INDEX(LAYOUT!$D$2:$D$80,MATCH(R2&"|"&M2,LAYOUT!$E$2:$E$80,0)),"CEK JENIS ZONA",IF($D2="","Zona STOCK",IF($E2="","CEK SKU DESCRIPTION kosong",IF(AND(O2<>"",P2=""),"CEK URUTAN SAMBUNG kosong",IF(AND(O2<>"",LEFT(R2,6)="Endcap"),"CEK Endcap tidak ikut sambung","OK")))))))))) | Z2: =IF(T2="","",IFERROR(INDEX(DAFTAR_FIXTURE!$B$2:$B$51,MATCH(T2,DAFTAR_FIXTURE!$A$2:$A$51,0)),"")) | AA2: =IF(T2="","",IF(Z2="","CEK ID FIXTURE tidak ada di DAFTAR_FIXTURE",IF(U2="","CEK ZONA NO kosong",IF(ISNA(MATCH(Z2&"|"&U2,LAYOUT!$E$2:$E$80,0)),"CEK ZONA NO di luar layout",IF(V2<>INDEX(LAYOUT!$D$2:$D$80,MATCH(Z2&"|"&U2,LAYOUT!$E$2:$E$80,0)),"CEK JENIS ZONA",IF($D2="","Zona STOCK",IF($E2="","CEK SKU DESCRIPTION kosong",IF(AND(W2<>"",X2=""),"CEK URUTAN SAMBUNG kosong",IF(AND(W2<>"",LEFT(Z2,6)="Endcap"),"CEK Endcap tidak ikut sambung","OK"))))))))) | AH2: =IF(AB2="","",IFERROR(INDEX(DAFTAR_FIXTURE!$B$2:$B$51,MATCH(AB2,DAFTAR_FIXTURE!$A$2:$A$51,0)),"")) | AI2: =IF(AB2="","",IF(AH2="","CEK ID FIXTURE tidak ada di DAFTAR_FIXTURE",IF(AC2="","CEK ZONA NO kosong",IF(ISNA(MATCH(AH2&"|"&AC2,LAYOUT!$E$2:$E$80,0)),"CEK ZONA NO di luar layout",IF(AD2<>INDEX(LAYOUT!$D$2:$D$80,MATCH(AH2&"|"&AC2,LAYOUT!$E$2:$E$80,0)),"CEK JENIS ZONA",IF($D2="","Zona STOCK",IF($E2="","CEK SKU DESCRIPTION kosong",IF(AND(AE2<>"",AF2=""),"CEK URUTAN SAMBUNG kosong",IF(AND(AE2<>"",LEFT(AH2,6)="Endcap"),"CEK Endcap tidak ikut sambung","OK")))))))))
A3: Homeware | B3: Tableware | C3: Serving Set | D3: 10681571 | E3: SERVING GLASS SQR PLATER ZEVY GOLD | G3: MAKAN | H3: A2. SERVINGWARE | I3: W/GOLD RACK GLASS | L3: GDN 4S | M3: 2 | N3: Shelving | R3: =IF(L3="","",IFERROR(INDEX(DAFTAR_FIXTURE!$B$2:$B$51,MATCH(L3,DAFTAR_FIXTURE!$A$2:$A$51,0)),"")) | S3: =IF(AND($D3="",L3=""),"",IF(L3="",IF(AND(T3="",AB3=""),"Belum ditempatkan",""),IF(R3="","CEK ID FIXTURE tidak ada di DAFTAR_FIXTURE",IF(M3="","CEK ZONA NO kosong",IF(ISNA(MATCH(R3&"|"&M3,LAYOUT!$E$2:$E$80,0)),"CEK ZONA NO di luar layout",IF(N3<>INDEX(LAYOUT!$D$2:$D$80,MATCH(R3&"|"&M3,LAYOUT!$E$2:$E$80,0)),"CEK JENIS ZONA",IF($D3="","Zona STOCK",IF($E3="","CEK SKU DESCRIPTION kosong",IF(AND(O3<>"",P3=""),"CEK URUTAN SAMBUNG kosong",IF(AND(O3<>"",LEFT(R3,6)="Endcap"),"CEK Endcap tidak ikut sambung","OK")))))))))) | T3: WLL 6S | U3: 1 | V3: Shelving | W3: WALL-RUN-1 | X3: 1 | Z3: =IF(T3="","",IFERROR(INDEX(DAFTAR_FIXTURE!$B$2:$B$51,MATCH(T3,DAFTAR_FIXTURE!$A$2:$A$51,0)),"")) | AA3: =IF(T3="","",IF(Z3="","CEK ID FIXTURE tidak ada di DAFTAR_FIXTURE",IF(U3="","CEK ZONA NO kosong",IF(ISNA(MATCH(Z3&"|"&U3,LAYOUT!$E$2:$E$80,0)),"CEK ZONA NO di luar layout",IF(V3<>INDEX(LAYOUT!$D$2:$D$80,MATCH(Z3&"|"&U3,LAYOUT!$E$2:$E$80,0)),"CEK JENIS ZONA",IF($D3="","Zona STOCK",IF($E3="","CEK SKU DESCRIPTION kosong",IF(AND(W3<>"",X3=""),"CEK URUTAN SAMBUNG kosong",IF(AND(W3<>"",LEFT(Z3,6)="Endcap"),"CEK Endcap tidak ikut sambung","OK"))))))))) | AH3: =IF(AB3="","",IFERROR(INDEX(DAFTAR_FIXTURE!$B$2:$B$51,MATCH(AB3,DAFTAR_FIXTURE!$A$2:$A$51,0)),"")) | AI3: =IF(AB3="","",IF(AH3="","CEK ID FIXTURE tidak ada di DAFTAR_FIXTURE",IF(AC3="","CEK ZONA NO kosong",IF(ISNA(MATCH(AH3&"|"&AC3,LAYOUT!$E$2:$E$80,0)),"CEK ZONA NO di luar layout",IF(AD3<>INDEX(LAYOUT!$D$2:$D$80,MATCH(AH3&"|"&AC3,LAYOUT!$E$2:$E$80,0)),"CEK JENIS ZONA",IF($D3="","Zona STOCK",IF($E3="","CEK SKU DESCRIPTION kosong",IF(AND(AE3<>"",AF3=""),"CEK URUTAN SAMBUNG kosong",IF(AND(AE3<>"",LEFT(AH3,6)="Endcap"),"CEK Endcap tidak ikut sambung","OK")))))))))
A4: Homeware | B4: Storage | C4: Food Storage | D4: 10682153 | E4: EID 2026 GLASS JAR SET OF 3 900ML | G4: PENYIMPANAN | H4: E4. CANISTER | I4: GLASS FANCY | L4: WLL 5S | M4: 1 | N4: Shelving | O4: WALL-RUN-1 | P4: 2 | R4: =IF(L4="","",IFERROR(INDEX(DAFTAR_FIXTURE!$B$2:$B$51,MATCH(L4,DAFTAR_FIXTURE!$A$2:$A$51,0)),"")) | S4: =IF(AND($D4="",L4=""),"",IF(L4="",IF(AND(T4="",AB4=""),"Belum ditempatkan",""),IF(R4="","CEK ID FIXTURE tidak ada di DAFTAR_FIXTURE",IF(M4="","CEK ZONA NO kosong",IF(ISNA(MATCH(R4&"|"&M4,LAYOUT!$E$2:$E$80,0)),"CEK ZONA NO di luar layout",IF(N4<>INDEX(LAYOUT!$D$2:$D$80,MATCH(R4&"|"&M4,LAYOUT!$E$2:$E$80,0)),"CEK JENIS ZONA",IF($D4="","Zona STOCK",IF($E4="","CEK SKU DESCRIPTION kosong",IF(AND(O4<>"",P4=""),"CEK URUTAN SAMBUNG kosong",IF(AND(O4<>"",LEFT(R4,6)="Endcap"),"CEK Endcap tidak ikut sambung","OK")))))))))) | Z4: =IF(T4="","",IFERROR(INDEX(DAFTAR_FIXTURE!$B$2:$B$51,MATCH(T4,DAFTAR_FIXTURE!$A$2:$A$51,0)),"")) | AA4: =IF(T4="","",IF(Z4="","CEK ID FIXTURE tidak ada di DAFTAR_FIXTURE",IF(U4="","CEK ZONA NO kosong",IF(ISNA(MATCH(Z4&"|"&U4,LAYOUT!$E$2:$E$80,0)),"CEK ZONA NO di luar layout",IF(V4<>INDEX(LAYOUT!$D$2:$D$80,MATCH(Z4&"|"&U4,LAYOUT!$E$2:$E$80,0)),"CEK JENIS ZONA",IF($D4="","Zona STOCK",IF($E4="","CEK SKU DESCRIPTION kosong",IF(AND(W4<>"",X4=""),"CEK URUTAN SAMBUNG kosong",IF(AND(W4<>"",LEFT(Z4,6)="Endcap"),"CEK Endcap tidak ikut sambung","OK"))))))))) | AH4: =IF(AB4="","",IFERROR(INDEX(DAFTAR_FIXTURE!$B$2:$B$51,MATCH(AB4,DAFTAR_FIXTURE!$A$2:$A$51,0)),"")) | AI4: =IF(AB4="","",IF(AH4="","CEK ID FIXTURE tidak ada di DAFTAR_FIXTURE",IF(AC4="","CEK ZONA NO kosong",IF(ISNA(MATCH(AH4&"|"&AC4,LAYOUT!$E$2:$E$80,0)),"CEK ZONA NO di luar layout",IF(AD4<>INDEX(LAYOUT!$D$2:$D$80,MATCH(AH4&"|"&AC4,LAYOUT!$E$2:$E$80,0)),"CEK JENIS ZONA",IF($D4="","Zona STOCK",IF($E4="","CEK SKU DESCRIPTION kosong",IF(AND(AE4<>"",AF4=""),"CEK URUTAN SAMBUNG kosong",IF(AND(AE4<>"",LEFT(AH4,6)="Endcap"),"CEK Endcap tidak ikut sambung","OK")))))))))
L5: GDN 2G + 2S | M5: 1 | N5: Gantungan | O5: GONDOLA-RUN-1 | P5: 2 | R5: =IF(L5="","",IFERROR(INDEX(DAFTAR_FIXTURE!$B$2:$B$51,MATCH(L5,DAFTAR_FIXTURE!$A$2:$A$51,0)),"")) | S5: =IF(AND($D5="",L5=""),"",IF(L5="",IF(AND(T5="",AB5=""),"Belum ditempatkan",""),IF(R5="","CEK ID FIXTURE tidak ada di DAFTAR_FIXTURE",IF(M5="","CEK ZONA NO kosong",IF(ISNA(MATCH(R5&"|"&M5,LAYOUT!$E$2:$E$80,0)),"CEK ZONA NO di luar layout",IF(N5<>INDEX(LAYOUT!$D$2:$D$80,MATCH(R5&"|"&M5,LAYOUT!$E$2:$E$80,0)),"CEK JENIS ZONA",IF($D5="","Zona STOCK",IF($E5="","CEK SKU DESCRIPTION kosong",IF(AND(O5<>"",P5=""),"CEK URUTAN SAMBUNG kosong",IF(AND(O5<>"",LEFT(R5,6)="Endcap"),"CEK Endcap tidak ikut sambung","OK")))))))))) | Z5: =IF(T5="","",IFERROR(INDEX(DAFTAR_FIXTURE!$B$2:$B$51,MATCH(T5,DAFTAR_FIXTURE!$A$2:$A$51,0)),"")) | AA5: =IF(T5="","",IF(Z5="","CEK ID FIXTURE tidak ada di DAFTAR_FIXTURE",IF(U5="","CEK ZONA NO kosong",IF(ISNA(MATCH(Z5&"|"&U5,LAYOUT!$E$2:$E$80,0)),"CEK ZONA NO di luar layout",IF(V5<>INDEX(LAYOUT!$D$2:$D$80,MATCH(Z5&"|"&U5,LAYOUT!$E$2:$E$80,0)),"CEK JENIS ZONA",IF($D5="","Zona STOCK",IF($E5="","CEK SKU DESCRIPTION kosong",IF(AND(W5<>"",X5=""),"CEK URUTAN SAMBUNG kosong",IF(AND(W5<>"",LEFT(Z5,6)="Endcap"),"CEK Endcap tidak ikut sambung","OK"))))))))) | AH5: =IF(AB5="","",IFERROR(INDEX(DAFTAR_FIXTURE!$B$2:$B$51,MATCH(AB5,DAFTAR_FIXTURE!$A$2:$A$51,0)),"")) | AI5: =IF(AB5="","",IF(AH5="","CEK ID FIXTURE tidak ada di DAFTAR_FIXTURE",IF(AC5="","CEK ZONA NO kosong",IF(ISNA(MATCH(AH5&"|"&AC5,LAYOUT!$E$2:$E$80,0)),"CEK ZONA NO di luar layout",IF(AD5<>INDEX(LAYOUT!$D$2:$D$80,MATCH(AH5&"|"&AC5,LAYOUT!$E$2:$E$80,0)),"CEK JENIS ZONA",IF($D5="","Zona STOCK",IF($E5="","CEK SKU DESCRIPTION kosong",IF(AND(AE5<>"",AF5=""),"CEK URUTAN SAMBUNG kosong",IF(AND(AE5<>"",LEFT(AH5,6)="Endcap"),"CEK Endcap tidak ikut sambung","OK")))))))))
L6: PLT 90 | M6: 1 | N6: Shelving | O6: PALLET-RUN-1 | P6: 1 | R6: =IF(L6="","",IFERROR(INDEX(DAFTAR_FIXTURE!$B$2:$B$51,MATCH(L6,DAFTAR_FIXTURE!$A$2:$A$51,0)),"")) | S6: =IF(AND($D6="",L6=""),"",IF(L6="",IF(AND(T6="",AB6=""),"Belum ditempatkan",""),IF(R6="","CEK ID FIXTURE tidak ada di DAFTAR_FIXTURE",IF(M6="","CEK ZONA NO kosong",IF(ISNA(MATCH(R6&"|"&M6,LAYOUT!$E$2:$E$80,0)),"CEK ZONA NO di luar layout",IF(N6<>INDEX(LAYOUT!$D$2:$D$80,MATCH(R6&"|"&M6,LAYOUT!$E$2:$E$80,0)),"CEK JENIS ZONA",IF($D6="","Zona STOCK",IF($E6="","CEK SKU DESCRIPTION kosong",IF(AND(O6<>"",P6=""),"CEK URUTAN SAMBUNG kosong",IF(AND(O6<>"",LEFT(R6,6)="Endcap"),"CEK Endcap tidak ikut sambung","OK")))))))))) | Z6: =IF(T6="","",IFERROR(INDEX(DAFTAR_FIXTURE!$B$2:$B$51,MATCH(T6,DAFTAR_FIXTURE!$A$2:$A$51,0)),"")) | AA6: =IF(T6="","",IF(Z6="","CEK ID FIXTURE tidak ada di DAFTAR_FIXTURE",IF(U6="","CEK ZONA NO kosong",IF(ISNA(MATCH(Z6&"|"&U6,LAYOUT!$E$2:$E$80,0)),"CEK ZONA NO di luar layout",IF(V6<>INDEX(LAYOUT!$D$2:$D$80,MATCH(Z6&"|"&U6,LAYOUT!$E$2:$E$80,0)),"CEK JENIS ZONA",IF($D6="","Zona STOCK",IF($E6="","CEK SKU DESCRIPTION kosong",IF(AND(W6<>"",X6=""),"CEK URUTAN SAMBUNG kosong",IF(AND(W6<>"",LEFT(Z6,6)="Endcap"),"CEK Endcap tidak ikut sambung","OK"))))))))) | AH6: =IF(AB6="","",IFERROR(INDEX(DAFTAR_FIXTURE!$B$2:$B$51,MATCH(AB6,DAFTAR_FIXTURE!$A$2:$A$51,0)),"")) | AI6: =IF(AB6="","",IF(AH6="","CEK ID FIXTURE tidak ada di DAFTAR_FIXTURE",IF(AC6="","CEK ZONA NO kosong",IF(ISNA(MATCH(AH6&"|"&AC6,LAYOUT!$E$2:$E$80,0)),"CEK ZONA NO di luar layout",IF(AD6<>INDEX(LAYOUT!$D$2:$D$80,MATCH(AH6&"|"&AC6,LAYOUT!$E$2:$E$80,0)),"CEK JENIS ZONA",IF($D6="","Zona STOCK",IF($E6="","CEK SKU DESCRIPTION kosong",IF(AND(AE6<>"",AF6=""),"CEK URUTAN SAMBUNG kosong",IF(AND(AE6<>"",LEFT(AH6,6)="Endcap"),"CEK Endcap tidak ikut sambung","OK")))))))))
R7: =IF(L7="","",IFERROR(INDEX(DAFTAR_FIXTURE!$B$2:$B$51,MATCH(L7,DAFTAR_FIXTURE!$A$2:$A$51,0)),"")) | S7: =IF(AND($D7="",L7=""),"",IF(L7="",IF(AND(T7="",AB7=""),"Belum ditempatkan",""),IF(R7="","CEK ID FIXTURE tidak ada di DAFTAR_FIXTURE",IF(M7="","CEK ZONA NO kosong",IF(ISNA(MATCH(R7&"|"&M7,LAYOUT!$E$2:$E$80,0)),"CEK ZONA NO di luar layout",IF(N7<>INDEX(LAYOUT!$D$2:$D$80,MATCH(R7&"|"&M7,LAYOUT!$E$2:$E$80,0)),"CEK JENIS ZONA",IF($D7="","Zona STOCK",IF($E7="","CEK SKU DESCRIPTION kosong",IF(AND(O7<>"",P7=""),"CEK URUTAN SAMBUNG kosong",IF(AND(O7<>"",LEFT(R7,6)="Endcap"),"CEK Endcap tidak ikut sambung","OK")))))))))) | Z7: =IF(T7="","",IFERROR(INDEX(DAFTAR_FIXTURE!$B$2:$B$51,MATCH(T7,DAFTAR_FIXTURE!$A$2:$A$51,0)),"")) | AA7: =IF(T7="","",IF(Z7="","CEK ID FIXTURE tidak ada di DAFTAR_FIXTURE",IF(U7="","CEK ZONA NO kosong",IF(ISNA(MATCH(Z7&"|"&U7,LAYOUT!$E$2:$E$80,0)),"CEK ZONA NO di luar layout",IF(V7<>INDEX(LAYOUT!$D$2:$D$80,MATCH(Z7&"|"&U7,LAYOUT!$E$2:$E$80,0)),"CEK JENIS ZONA",IF($D7="","Zona STOCK",IF($E7="","CEK SKU DESCRIPTION kosong",IF(AND(W7<>"",X7=""),"CEK URUTAN SAMBUNG kosong",IF(AND(W7<>"",LEFT(Z7,6)="Endcap"),"CEK Endcap tidak ikut sambung","OK"))))))))) | AH7: =IF(AB7="","",IFERROR(INDEX(DAFTAR_FIXTURE!$B$2:$B$51,MATCH(AB7,DAFTAR_FIXTURE!$A$2:$A$51,0)),"")) | AI7: =IF(AB7="","",IF(AH7="","CEK ID FIXTURE tidak ada di DAFTAR_FIXTURE",IF(AC7="","CEK ZONA NO kosong",IF(ISNA(MATCH(AH7&"|"&AC7,LAYOUT!$E$2:$E$80,0)),"CEK ZONA NO di luar layout",IF(AD7<>INDEX(LAYOUT!$D$2:$D$80,MATCH(AH7&"|"&AC7,LAYOUT!$E$2:$E$80,0)),"CEK JENIS ZONA",IF($D7="","Zona STOCK",IF($E7="","CEK SKU DESCRIPTION kosong",IF(AND(AE7<>"",AF7=""),"CEK URUTAN SAMBUNG kosong",IF(AND(AE7<>"",LEFT(AH7,6)="Endcap"),"CEK Endcap tidak ikut sambung","OK")))))))))
R8: =IF(L8="","",IFERROR(INDEX(DAFTAR_FIXTURE!$B$2:$B$51,MATCH(L8,DAFTAR_FIXTURE!$A$2:$A$51,0)),"")) | S8: =IF(AND($D8="",L8=""),"",IF(L8="",IF(AND(T8="",AB8=""),"Belum ditempatkan",""),IF(R8="","CEK ID FIXTURE tidak ada di DAFTAR_FIXTURE",IF(M8="","CEK ZONA NO kosong",IF(ISNA(MATCH(R8&"|"&M8,LAYOUT!$E$2:$E$80,0)),"CEK ZONA NO di luar layout",IF(N8<>INDEX(LAYOUT!$D$2:$D$80,MATCH(R8&"|"&M8,LAYOUT!$E$2:$E$80,0)),"CEK JENIS ZONA",IF($D8="","Zona STOCK",IF($E8="","CEK SKU DESCRIPTION kosong",IF(AND(O8<>"",P8=""),"CEK URUTAN SAMBUNG kosong",IF(AND(O8<>"",LEFT(R8,6)="Endcap"),"CEK Endcap tidak ikut sambung","OK")))))))))) | Z8: =IF(T8="","",IFERROR(INDEX(DAFTAR_FIXTURE!$B$2:$B$51,MATCH(T8,DAFTAR_FIXTURE!$A$2:$A$51,0)),"")) | AA8: =IF(T8="","",IF(Z8="","CEK ID FIXTURE tidak ada di DAFTAR_FIXTURE",IF(U8="","CEK ZONA NO kosong",IF(ISNA(MATCH(Z8&"|"&U8,LAYOUT!$E$2:$E$80,0)),"CEK ZONA NO di luar layout",IF(V8<>INDEX(LAYOUT!$D$2:$D$80,MATCH(Z8&"|"&U8,LAYOUT!$E$2:$E$80,0)),"CEK JENIS ZONA",IF($D8="","Zona STOCK",IF($E8="","CEK SKU DESCRIPTION kosong",IF(AND(W8<>"",X8=""),"CEK URUTAN SAMBUNG kosong",IF(AND(W8<>"",LEFT(Z8,6)="Endcap"),"CEK Endcap tidak ikut sambung","OK"))))))))) | AH8: =IF(AB8="","",IFERROR(INDEX(DAFTAR_FIXTURE!$B$2:$B$51,MATCH(AB8,DAFTAR_FIXTURE!$A$2:$A$51,0)),"")) | AI8: =IF(AB8="","",IF(AH8="","CEK ID FIXTURE tidak ada di DAFTAR_FIXTURE",IF(AC8="","CEK ZONA NO kosong",IF(ISNA(MATCH(AH8&"|"&AC8,LAYOUT!$E$2:$E$80,0)),"CEK ZONA NO di luar layout",IF(AD8<>INDEX(LAYOUT!$D$2:$D$80,MATCH(AH8&"|"&AC8,LAYOUT!$E$2:$E$80,0)),"CEK JENIS ZONA",IF($D8="","Zona STOCK",IF($E8="","CEK SKU DESCRIPTION kosong",IF(AND(AE8<>"",AF8=""),"CEK URUTAN SAMBUNG kosong",IF(AND(AE8<>"",LEFT(AH8,6)="Endcap"),"CEK Endcap tidak ikut sambung","OK")))))))))
R9: =IF(L9="","",IFERROR(INDEX(DAFTAR_FIXTURE!$B$2:$B$51,MATCH(L9,DAFTAR_FIXTURE!$A$2:$A$51,0)),"")) | S9: =IF(AND($D9="",L9=""),"",IF(L9="",IF(AND(T9="",AB9=""),"Belum ditempatkan",""),IF(R9="","CEK ID FIXTURE tidak ada di DAFTAR_FIXTURE",IF(M9="","CEK ZONA NO kosong",IF(ISNA(MATCH(R9&"|"&M9,LAYOUT!$E$2:$E$80,0)),"CEK ZONA NO di luar layout",IF(N9<>INDEX(LAYOUT!$D$2:$D$80,MATCH(R9&"|"&M9,LAYOUT!$E$2:$E$80,0)),"CEK JENIS ZONA",IF($D9="","Zona STOCK",IF($E9="","CEK SKU DESCRIPTION kosong",IF(AND(O9<>"",P9=""),"CEK URUTAN SAMBUNG kosong",IF(AND(O9<>"",LEFT(R9,6)="Endcap"),"CEK Endcap tidak ikut sambung","OK")))))))))) | Z9: =IF(T9="","",IFERROR(INDEX(DAFTAR_FIXTURE!$B$2:$B$51,MATCH(T9,DAFTAR_FIXTURE!$A$2:$A$51,0)),"")) | AA9: =IF(T9="","",IF(Z9="","CEK ID FIXTURE tidak ada di DAFTAR_FIXTURE",IF(U9="","CEK ZONA NO kosong",IF(ISNA(MATCH(Z9&"|"&U9,LAYOUT!$E$2:$E$80,0)),"CEK ZONA NO di luar layout",IF(V9<>INDEX(LAYOUT!$D$2:$D$80,MATCH(Z9&"|"&U9,LAYOUT!$E$2:$E$80,0)),"CEK JENIS ZONA",IF($D9="","Zona STOCK",IF($E9="","CEK SKU DESCRIPTION kosong",IF(AND(W9<>"",X9=""),"CEK URUTAN SAMBUNG kosong",IF(AND(W9<>"",LEFT(Z9,6)="Endcap"),"CEK Endcap tidak ikut sambung","OK"))))))))) | AH9: =IF(AB9="","",IFERROR(INDEX(DAFTAR_FIXTURE!$B$2:$B$51,MATCH(AB9,DAFTAR_FIXTURE!$A$2:$A$51,0)),"")) | AI9: =IF(AB9="","",IF(AH9="","CEK ID FIXTURE tidak ada di DAFTAR_FIXTURE",IF(AC9="","CEK ZONA NO kosong",IF(ISNA(MATCH(AH9&"|"&AC9,LAYOUT!$E$2:$E$80,0)),"CEK ZONA NO di luar layout",IF(AD9<>INDEX(LAYOUT!$D$2:$D$80,MATCH(AH9&"|"&AC9,LAYOUT!$E$2:$E$80,0)),"CEK JENIS ZONA",IF($D9="","Zona STOCK",IF($E9="","CEK SKU DESCRIPTION kosong",IF(AND(AE9<>"",AF9=""),"CEK URUTAN SAMBUNG kosong",IF(AND(AE9<>"",LEFT(AH9,6)="Endcap"),"CEK Endcap tidak ikut sambung","OK")))))))))
R10: =IF(L10="","",IFERROR(INDEX(DAFTAR_FIXTURE!$B$2:$B$51,MATCH(L10,DAFTAR_FIXTURE!$A$2:$A$51,0)),"")) | S10: =IF(AND($D10="",L10=""),"",IF(L10="",IF(AND(T10="",AB10=""),"Belum ditempatkan",""),IF(R10="","CEK ID FIXTURE tidak ada di DAFTAR_FIXTURE",IF(M10="","CEK ZONA NO kosong",IF(ISNA(MATCH(R10&"|"&M10,LAYOUT!$E$2:$E$80,0)),"CEK ZONA NO di luar layout",IF(N10<>INDEX(LAYOUT!$D$2:$D$80,MATCH(R10&"|"&M10,LAYOUT!$E$2:$E$80,0)),"CEK JENIS ZONA",IF($D10="","Zona STOCK",IF($E10="","CEK SKU DESCRIPTION kosong",IF(AND(O10<>"",P10=""),"CEK URUTAN SAMBUNG kosong",IF(AND(O10<>"",LEFT(R10,6)="Endcap"),"CEK Endcap tidak ikut sambung","OK")))))))))) | Z10: =IF(T10="","",IFERROR(INDEX(DAFTAR_FIXTURE!$B$2:$B$51,MATCH(T10,DAFTAR_FIXTURE!$A$2:$A$51,0)),"")) | AA10: =IF(T10="","",IF(Z10="","CEK ID FIXTURE tidak ada di DAFTAR_FIXTURE",IF(U10="","CEK ZONA NO kosong",IF(ISNA(MATCH(Z10&"|"&U10,LAYOUT!$E$2:$E$80,0)),"CEK ZONA NO di luar layout",IF(V10<>INDEX(LAYOUT!$D$2:$D$80,MATCH(Z10&"|"&U10,LAYOUT!$E$2:$E$80,0)),"CEK JENIS ZONA",IF($D10="","Zona STOCK",IF($E10="","CEK SKU DESCRIPTION kosong",IF(AND(W10<>"",X10=""),"CEK URUTAN SAMBUNG kosong",IF(AND(W10<>"",LEFT(Z10,6)="Endcap"),"CEK Endcap tidak ikut sambung","OK"))))))))) | AH10: =IF(AB10="","",IFERROR(INDEX(DAFTAR_FIXTURE!$B$2:$B$51,MATCH(AB10,DAFTAR_FIXTURE!$A$2:$A$51,0)),"")) | AI10: =IF(AB10="","",IF(AH10="","CEK ID FIXTURE tidak ada di DAFTAR_FIXTURE",IF(AC10="","CEK ZONA NO kosong",IF(ISNA(MATCH(AH10&"|"&AC10,LAYOUT!$E$2:$E$80,0)),"CEK ZONA NO di luar layout",IF(AD10<>INDEX(LAYOUT!$D$2:$D$80,MATCH(AH10&"|"&AC10,LAYOUT!$E$2:$E$80,0)),"CEK JENIS ZONA",IF($D10="","Zona STOCK",IF($E10="","CEK SKU DESCRIPTION kosong",IF(AND(AE10<>"",AF10=""),"CEK URUTAN SAMBUNG kosong",IF(AND(AE10<>"",LEFT(AH10,6)="Endcap"),"CEK Endcap tidak ikut sambung","OK")))))))))
R11: =IF(L11="","",IFERROR(INDEX(DAFTAR_FIXTURE!$B$2:$B$51,MATCH(L11,DAFTAR_FIXTURE!$A$2:$A$51,0)),"")) | S11: =IF(AND($D11="",L11=""),"",IF(L11="",IF(AND(T11="",AB11=""),"Belum ditempatkan",""),IF(R11="","CEK ID FIXTURE tidak ada di DAFTAR_FIXTURE",IF(M11="","CEK ZONA NO kosong",IF(ISNA(MATCH(R11&"|"&M11,LAYOUT!$E$2:$E$80,0)),"CEK ZONA NO di luar layout",IF(N11<>INDEX(LAYOUT!$D$2:$D$80,MATCH(R11&"|"&M11,LAYOUT!$E$2:$E$80,0)),"CEK JENIS ZONA",IF($D11="","Zona STOCK",IF($E11="","CEK SKU DESCRIPTION kosong",IF(AND(O11<>"",P11=""),"CEK URUTAN SAMBUNG kosong",IF(AND(O11<>"",LEFT(R11,6)="Endcap"),"CEK Endcap tidak ikut sambung","OK")))))))))) | Z11: =IF(T11="","",IFERROR(INDEX(DAFTAR_FIXTURE!$B$2:$B$51,MATCH(T11,DAFTAR_FIXTURE!$A$2:$A$51,0)),"")) | AA11: =IF(T11="","",IF(Z11="","CEK ID FIXTURE tidak ada di DAFTAR_FIXTURE",IF(U11="","CEK ZONA NO kosong",IF(ISNA(MATCH(Z11&"|"&U11,LAYOUT!$E$2:$E$80,0)),"CEK ZONA NO di luar layout",IF(V11<>INDEX(LAYOUT!$D$2:$D$80,MATCH(Z11&"|"&U11,LAYOUT!$E$2:$E$80,0)),"CEK JENIS ZONA",IF($D11="","Zona STOCK",IF($E11="","CEK SKU DESCRIPTION kosong",IF(AND(W11<>"",X11=""),"CEK URUTAN SAMBUNG kosong",IF(AND(W11<>"",LEFT(Z11,6)="Endcap"),"CEK Endcap tidak ikut sambung","OK"))))))))) | AH11: =IF(AB11="","",IFERROR(INDEX(DAFTAR_FIXTURE!$B$2:$B$51,MATCH(AB11,DAFTAR_FIXTURE!$A$2:$A$51,0)),"")) | AI11: =IF(AB11="","",IF(AH11="","CEK ID FIXTURE tidak ada di DAFTAR_FIXTURE",IF(AC11="","CEK ZONA NO kosong",IF(ISNA(MATCH(AH11&"|"&AC11,LAYOUT!$E$2:$E$80,0)),"CEK ZONA NO di luar layout",IF(AD11<>INDEX(LAYOUT!$D$2:$D$80,MATCH(AH11&"|"&AC11,LAYOUT!$E$2:$E$80,0)),"CEK JENIS ZONA",IF($D11="","Zona STOCK",IF($E11="","CEK SKU DESCRIPTION kosong",IF(AND(AE11<>"",AF11=""),"CEK URUTAN SAMBUNG kosong",IF(AND(AE11<>"",LEFT(AH11,6)="Endcap"),"CEK Endcap tidak ikut sambung","OK")))))))))
R12: =IF(L12="","",IFERROR(INDEX(DAFTAR_FIXTURE!$B$2:$B$51,MATCH(L12,DAFTAR_FIXTURE!$A$2:$A$51,0)),"")) | S12: =IF(AND($D12="",L12=""),"",IF(L12="",IF(AND(T12="",AB12=""),"Belum ditempatkan",""),IF(R12="","CEK ID FIXTURE tidak ada di DAFTAR_FIXTURE",IF(M12="","CEK ZONA NO kosong",IF(ISNA(MATCH(R12&"|"&M12,LAYOUT!$E$2:$E$80,0)),"CEK ZONA NO di luar layout",IF(N12<>INDEX(LAYOUT!$D$2:$D$80,MATCH(R12&"|"&M12,LAYOUT!$E$2:$E$80,0)),"CEK JENIS ZONA",IF($D12="","Zona STOCK",IF($E12="","CEK SKU DESCRIPTION kosong",IF(AND(O12<>"",P12=""),"CEK URUTAN SAMBUNG kosong",IF(AND(O12<>"",LEFT(R12,6)="Endcap"),"CEK Endcap tidak ikut sambung","OK")))))))))) | Z12: =IF(T12="","",IFERROR(INDEX(DAFTAR_FIXTURE!$B$2:$B$51,MATCH(T12,DAFTAR_FIXTURE!$A$2:$A$51,0)),"")) | AA12: =IF(T12="","",IF(Z12="","CEK ID FIXTURE tidak ada di DAFTAR_FIXTURE",IF(U12="","CEK ZONA NO kosong",IF(ISNA(MATCH(Z12&"|"&U12,LAYOUT!$E$2:$E$80,0)),"CEK ZONA NO di luar layout",IF(V12<>INDEX(LAYOUT!$D$2:$D$80,MATCH(Z12&"|"&U12,LAYOUT!$E$2:$E$80,0)),"CEK JENIS ZONA",IF($D12="","Zona STOCK",IF($E12="","CEK SKU DESCRIPTION kosong",IF(AND(W12<>"",X12=""),"CEK URUTAN SAMBUNG kosong",IF(AND(W12<>"",LEFT(Z12,6)="Endcap"),"CEK Endcap tidak ikut sambung","OK"))))))))) | AH12: =IF(AB12="","",IFERROR(INDEX(DAFTAR_FIXTURE!$B$2:$B$51,MATCH(AB12,DAFTAR_FIXTURE!$A$2:$A$51,0)),"")) | AI12: =IF(AB12="","",IF(AH12="","CEK ID FIXTURE tidak ada di DAFTAR_FIXTURE",IF(AC12="","CEK ZONA NO kosong",IF(ISNA(MATCH(AH12&"|"&AC12,LAYOUT!$E$2:$E$80,0)),"CEK ZONA NO di luar layout",IF(AD12<>INDEX(LAYOUT!$D$2:$D$80,MATCH(AH12&"|"&AC12,LAYOUT!$E$2:$E$80,0)),"CEK JENIS ZONA",IF($D12="","Zona STOCK",IF($E12="","CEK SKU DESCRIPTION kosong",IF(AND(AE12<>"",AF12=""),"CEK URUTAN SAMBUNG kosong",IF(AND(AE12<>"",LEFT(AH12,6)="Endcap"),"CEK Endcap tidak ikut sambung","OK")))))))))
R13: =IF(L13="","",IFERROR(INDEX(DAFTAR_FIXTURE!$B$2:$B$51,MATCH(L13,DAFTAR_FIXTURE!$A$2:$A$51,0)),"")) | S13: =IF(AND($D13="",L13=""),"",IF(L13="",IF(AND(T13="",AB13=""),"Belum ditempatkan",""),IF(R13="","CEK ID FIXTURE tidak ada di DAFTAR_FIXTURE",IF(M13="","CEK ZONA NO kosong",IF(ISNA(MATCH(R13&"|"&M13,LAYOUT!$E$2:$E$80,0)),"CEK ZONA NO di luar layout",IF(N13<>INDEX(LAYOUT!$D$2:$D$80,MATCH(R13&"|"&M13,LAYOUT!$E$2:$E$80,0)),"CEK JENIS ZONA",IF($D13="","Zona STOCK",IF($E13="","CEK SKU DESCRIPTION kosong",IF(AND(O13<>"",P13=""),"CEK URUTAN SAMBUNG kosong",IF(AND(O13<>"",LEFT(R13,6)="Endcap"),"CEK Endcap tidak ikut sambung","OK")))))))))) | Z13: =IF(T13="","",IFERROR(INDEX(DAFTAR_FIXTURE!$B$2:$B$51,MATCH(T13,DAFTAR_FIXTURE!$A$2:$A$51,0)),"")) | AA13: =IF(T13="","",IF(Z13="","CEK ID FIXTURE tidak ada di DAFTAR_FIXTURE",IF(U13="","CEK ZONA NO kosong",IF(ISNA(MATCH(Z13&"|"&U13,LAYOUT!$E$2:$E$80,0)),"CEK ZONA NO di luar layout",IF(V13<>INDEX(LAYOUT!$D$2:$D$80,MATCH(Z13&"|"&U13,LAYOUT!$E$2:$E$80,0)),"CEK JENIS ZONA",IF($D13="","Zona STOCK",IF($E13="","CEK SKU DESCRIPTION kosong",IF(AND(W13<>"",X13=""),"CEK URUTAN SAMBUNG kosong",IF(AND(W13<>"",LEFT(Z13,6)="Endcap"),"CEK Endcap tidak ikut sambung","OK"))))))))) | AH13: =IF(AB13="","",IFERROR(INDEX(DAFTAR_FIXTURE!$B$2:$B$51,MATCH(AB13,DAFTAR_FIXTURE!$A$2:$A$51,0)),"")) | AI13: =IF(AB13="","",IF(AH13="","CEK ID FIXTURE tidak ada di DAFTAR_FIXTURE",IF(AC13="","CEK ZONA NO kosong",IF(ISNA(MATCH(AH13&"|"&AC13,LAYOUT!$E$2:$E$80,0)),"CEK ZONA NO di luar layout",IF(AD13<>INDEX(LAYOUT!$D$2:$D$80,MATCH(AH13&"|"&AC13,LAYOUT!$E$2:$E$80,0)),"CEK JENIS ZONA",IF($D13="","Zona STOCK",IF($E13="","CEK SKU DESCRIPTION kosong",IF(AND(AE13<>"",AF13=""),"CEK URUTAN SAMBUNG kosong",IF(AND(AE13<>"",LEFT(AH13,6)="Endcap"),"CEK Endcap tidak ikut sambung","OK")))))))))
R14: =IF(L14="","",IFERROR(INDEX(DAFTAR_FIXTURE!$B$2:$B$51,MATCH(L14,DAFTAR_FIXTURE!$A$2:$A$51,0)),"")) | S14: =IF(AND($D14="",L14=""),"",IF(L14="",IF(AND(T14="",AB14=""),"Belum ditempatkan",""),IF(R14="","CEK ID FIXTURE tidak ada di DAFTAR_FIXTURE",IF(M14="","CEK ZONA NO kosong",IF(ISNA(MATCH(R14&"|"&M14,LAYOUT!$E$2:$E$80,0)),"CEK ZONA NO di luar layout",IF(N14<>INDEX(LAYOUT!$D$2:$D$80,MATCH(R14&"|"&M14,LAYOUT!$E$2:$E$80,0)),"CEK JENIS ZONA",IF($D14="","Zona STOCK",IF($E14="","CEK SKU DESCRIPTION kosong",IF(AND(O14<>"",P14=""),"CEK URUTAN SAMBUNG kosong",IF(AND(O14<>"",LEFT(R14,6)="Endcap"),"CEK Endcap tidak ikut sambung","OK")))))))))) | Z14: =IF(T14="","",IFERROR(INDEX(DAFTAR_FIXTURE!$B$2:$B$51,MATCH(T14,DAFTAR_FIXTURE!$A$2:$A$51,0)),"")) | AA14: =IF(T14="","",IF(Z14="","CEK ID FIXTURE tidak ada di DAFTAR_FIXTURE",IF(U14="","CEK ZONA NO kosong",IF(ISNA(MATCH(Z14&"|"&U14,LAYOUT!$E$2:$E$80,0)),"CEK ZONA NO di luar layout",IF(V14<>INDEX(LAYOUT!$D$2:$D$80,MATCH(Z14&"|"&U14,LAYOUT!$E$2:$E$80,0)),"CEK JENIS ZONA",IF($D14="","Zona STOCK",IF($E14="","CEK SKU DESCRIPTION kosong",IF(AND(W14<>"",X14=""),"CEK URUTAN SAMBUNG kosong",IF(AND(W14<>"",LEFT(Z14,6)="Endcap"),"CEK Endcap tidak ikut sambung","OK"))))))))) | AH14: =IF(AB14="","",IFERROR(INDEX(DAFTAR_FIXTURE!$B$2:$B$51,MATCH(AB14,DAFTAR_FIXTURE!$A$2:$A$51,0)),"")) | AI14: =IF(AB14="","",IF(AH14="","CEK ID FIXTURE tidak ada di DAFTAR_FIXTURE",IF(AC14="","CEK ZONA NO kosong",IF(ISNA(MATCH(AH14&"|"&AC14,LAYOUT!$E$2:$E$80,0)),"CEK ZONA NO di luar layout",IF(AD14<>INDEX(LAYOUT!$D$2:$D$80,MATCH(AH14&"|"&AC14,LAYOUT!$E$2:$E$80,0)),"CEK JENIS ZONA",IF($D14="","Zona STOCK",IF($E14="","CEK SKU DESCRIPTION kosong",IF(AND(AE14<>"",AF14=""),"CEK URUTAN SAMBUNG kosong",IF(AND(AE14<>"",LEFT(AH14,6)="Endcap"),"CEK Endcap tidak ikut sambung","OK")))))))))
R15: =IF(L15="","",IFERROR(INDEX(DAFTAR_FIXTURE!$B$2:$B$51,MATCH(L15,DAFTAR_FIXTURE!$A$2:$A$51,0)),"")) | S15: =IF(AND($D15="",L15=""),"",IF(L15="",IF(AND(T15="",AB15=""),"Belum ditempatkan",""),IF(R15="","CEK ID FIXTURE tidak ada di DAFTAR_FIXTURE",IF(M15="","CEK ZONA NO kosong",IF(ISNA(MATCH(R15&"|"&M15,LAYOUT!$E$2:$E$80,0)),"CEK ZONA NO di luar layout",IF(N15<>INDEX(LAYOUT!$D$2:$D$80,MATCH(R15&"|"&M15,LAYOUT!$E$2:$E$80,0)),"CEK JENIS ZONA",IF($D15="","Zona STOCK",IF($E15="","CEK SKU DESCRIPTION kosong",IF(AND(O15<>"",P15=""),"CEK URUTAN SAMBUNG kosong",IF(AND(O15<>"",LEFT(R15,6)="Endcap"),"CEK Endcap tidak ikut sambung","OK")))))))))) | Z15: =IF(T15="","",IFERROR(INDEX(DAFTAR_FIXTURE!$B$2:$B$51,MATCH(T15,DAFTAR_FIXTURE!$A$2:$A$51,0)),"")) | AA15: =IF(T15="","",IF(Z15="","CEK ID FIXTURE tidak ada di DAFTAR_FIXTURE",IF(U15="","CEK ZONA NO kosong",IF(ISNA(MATCH(Z15&"|"&U15,LAYOUT!$E$2:$E$80,0)),"CEK ZONA NO di luar layout",IF(V15<>INDEX(LAYOUT!$D$2:$D$80,MATCH(Z15&"|"&U15,LAYOUT!$E$2:$E$80,0)),"CEK JENIS ZONA",IF($D15="","Zona STOCK",IF($E15="","CEK SKU DESCRIPTION kosong",IF(AND(W15<>"",X15=""),"CEK URUTAN SAMBUNG kosong",IF(AND(W15<>"",LEFT(Z15,6)="Endcap"),"CEK Endcap tidak ikut sambung","OK"))))))))) | AH15: =IF(AB15="","",IFERROR(INDEX(DAFTAR_FIXTURE!$B$2:$B$51,MATCH(AB15,DAFTAR_FIXTURE!$A$2:$A$51,0)),"")) | AI15: =IF(AB15="","",IF(AH15="","CEK ID FIXTURE tidak ada di DAFTAR_FIXTURE",IF(AC15="","CEK ZONA NO kosong",IF(ISNA(MATCH(AH15&"|"&AC15,LAYOUT!$E$2:$E$80,0)),"CEK ZONA NO di luar layout",IF(AD15<>INDEX(LAYOUT!$D$2:$D$80,MATCH(AH15&"|"&AC15,LAYOUT!$E$2:$E$80,0)),"CEK JENIS ZONA",IF($D15="","Zona STOCK",IF($E15="","CEK SKU DESCRIPTION kosong",IF(AND(AE15<>"",AF15=""),"CEK URUTAN SAMBUNG kosong",IF(AND(AE15<>"",LEFT(AH15,6)="Endcap"),"CEK Endcap tidak ikut sambung","OK")))))))))
R16: =IF(L16="","",IFERROR(INDEX(DAFTAR_FIXTURE!$B$2:$B$51,MATCH(L16,DAFTAR_FIXTURE!$A$2:$A$51,0)),"")) | S16: =IF(AND($D16="",L16=""),"",IF(L16="",IF(AND(T16="",AB16=""),"Belum ditempatkan",""),IF(R16="","CEK ID FIXTURE tidak ada di DAFTAR_FIXTURE",IF(M16="","CEK ZONA NO kosong",IF(ISNA(MATCH(R16&"|"&M16,LAYOUT!$E$2:$E$80,0)),"CEK ZONA NO di luar layout",IF(N16<>INDEX(LAYOUT!$D$2:$D$80,MATCH(R16&"|"&M16,LAYOUT!$E$2:$E$80,0)),"CEK JENIS ZONA",IF($D16="","Zona STOCK",IF($E16="","CEK SKU DESCRIPTION kosong",IF(AND(O16<>"",P16=""),"CEK URUTAN SAMBUNG kosong",IF(AND(O16<>"",LEFT(R16,6)="Endcap"),"CEK Endcap tidak ikut sambung","OK")))))))))) | Z16: =IF(T16="","",IFERROR(INDEX(DAFTAR_FIXTURE!$B$2:$B$51,MATCH(T16,DAFTAR_FIXTURE!$A$2:$A$51,0)),"")) | AA16: =IF(T16="","",IF(Z16="","CEK ID FIXTURE tidak ada di DAFTAR_FIXTURE",IF(U16="","CEK ZONA NO kosong",IF(ISNA(MATCH(Z16&"|"&U16,LAYOUT!$E$2:$E$80,0)),"CEK ZONA NO di luar layout",IF(V16<>INDEX(LAYOUT!$D$2:$D$80,MATCH(Z16&"|"&U16,LAYOUT!$E$2:$E$80,0)),"CEK JENIS ZONA",IF($D16="","Zona STOCK",IF($E16="","CEK SKU DESCRIPTION kosong",IF(AND(W16<>"",X16=""),"CEK URUTAN SAMBUNG kosong",IF(AND(W16<>"",LEFT(Z16,6)="Endcap"),"CEK Endcap tidak ikut sambung","OK"))))))))) | AH16: =IF(AB16="","",IFERROR(INDEX(DAFTAR_FIXTURE!$B$2:$B$51,MATCH(AB16,DAFTAR_FIXTURE!$A$2:$A$51,0)),"")) | AI16: =IF(AB16="","",IF(AH16="","CEK ID FIXTURE tidak ada di DAFTAR_FIXTURE",IF(AC16="","CEK ZONA NO kosong",IF(ISNA(MATCH(AH16&"|"&AC16,LAYOUT!$E$2:$E$80,0)),"CEK ZONA NO di luar layout",IF(AD16<>INDEX(LAYOUT!$D$2:$D$80,MATCH(AH16&"|"&AC16,LAYOUT!$E$2:$E$80,0)),"CEK JENIS ZONA",IF($D16="","Zona STOCK",IF($E16="","CEK SKU DESCRIPTION kosong",IF(AND(AE16<>"",AF16=""),"CEK URUTAN SAMBUNG kosong",IF(AND(AE16<>"",LEFT(AH16,6)="Endcap"),"CEK Endcap tidak ikut sambung","OK")))))))))
R17: =IF(L17="","",IFERROR(INDEX(DAFTAR_FIXTURE!$B$2:$B$51,MATCH(L17,DAFTAR_FIXTURE!$A$2:$A$51,0)),"")) | S17: =IF(AND($D17="",L17=""),"",IF(L17="",IF(AND(T17="",AB17=""),"Belum ditempatkan",""),IF(R17="","CEK ID FIXTURE tidak ada di DAFTAR_FIXTURE",IF(M17="","CEK ZONA NO kosong",IF(ISNA(MATCH(R17&"|"&M17,LAYOUT!$E$2:$E$80,0)),"CEK ZONA NO di luar layout",IF(N17<>INDEX(LAYOUT!$D$2:$D$80,MATCH(R17&"|"&M17,LAYOUT!$E$2:$E$80,0)),"CEK JENIS ZONA",IF($D17="","Zona STOCK",IF($E17="","CEK SKU DESCRIPTION kosong",IF(AND(O17<>"",P17=""),"CEK URUTAN SAMBUNG kosong",IF(AND(O17<>"",LEFT(R17,6)="Endcap"),"CEK Endcap tidak ikut sambung","OK")))))))))) | Z17: =IF(T17="","",IFERROR(INDEX(DAFTAR_FIXTURE!$B$2:$B$51,MATCH(T17,DAFTAR_FIXTURE!$A$2:$A$51,0)),"")) | AA17: =IF(T17="","",IF(Z17="","CEK ID FIXTURE tidak ada di DAFTAR_FIXTURE",IF(U17="","CEK ZONA NO kosong",IF(ISNA(MATCH(Z17&"|"&U17,LAYOUT!$E$2:$E$80,0)),"CEK ZONA NO di luar layout",IF(V17<>INDEX(LAYOUT!$D$2:$D$80,MATCH(Z17&"|"&U17,LAYOUT!$E$2:$E$80,0)),"CEK JENIS ZONA",IF($D17="","Zona STOCK",IF($E17="","CEK SKU DESCRIPTION kosong",IF(AND(W17<>"",X17=""),"CEK URUTAN SAMBUNG kosong",IF(AND(W17<>"",LEFT(Z17,6)="Endcap"),"CEK Endcap tidak ikut sambung","OK"))))))))) | AH17: =IF(AB17="","",IFERROR(INDEX(DAFTAR_FIXTURE!$B$2:$B$51,MATCH(AB17,DAFTAR_FIXTURE!$A$2:$A$51,0)),"")) | AI17: =IF(AB17="","",IF(AH17="","CEK ID FIXTURE tidak ada di DAFTAR_FIXTURE",IF(AC17="","CEK ZONA NO kosong",IF(ISNA(MATCH(AH17&"|"&AC17,LAYOUT!$E$2:$E$80,0)),"CEK ZONA NO di luar layout",IF(AD17<>INDEX(LAYOUT!$D$2:$D$80,MATCH(AH17&"|"&AC17,LAYOUT!$E$2:$E$80,0)),"CEK JENIS ZONA",IF($D17="","Zona STOCK",IF($E17="","CEK SKU DESCRIPTION kosong",IF(AND(AE17<>"",AF17=""),"CEK URUTAN SAMBUNG kosong",IF(AND(AE17<>"",LEFT(AH17,6)="Endcap"),"CEK Endcap tidak ikut sambung","OK")))))))))
R18: =IF(L18="","",IFERROR(INDEX(DAFTAR_FIXTURE!$B$2:$B$51,MATCH(L18,DAFTAR_FIXTURE!$A$2:$A$51,0)),"")) | S18: =IF(AND($D18="",L18=""),"",IF(L18="",IF(AND(T18="",AB18=""),"Belum ditempatkan",""),IF(R18="","CEK ID FIXTURE tidak ada di DAFTAR_FIXTURE",IF(M18="","CEK ZONA NO kosong",IF(ISNA(MATCH(R18&"|"&M18,LAYOUT!$E$2:$E$80,0)),"CEK ZONA NO di luar layout",IF(N18<>INDEX(LAYOUT!$D$2:$D$80,MATCH(R18&"|"&M18,LAYOUT!$E$2:$E$80,0)),"CEK JENIS ZONA",IF($D18="","Zona STOCK",IF($E18="","CEK SKU DESCRIPTION kosong",IF(AND(O18<>"",P18=""),"CEK URUTAN SAMBUNG kosong",IF(AND(O18<>"",LEFT(R18,6)="Endcap"),"CEK Endcap tidak ikut sambung","OK")))))))))) | Z18: =IF(T18="","",IFERROR(INDEX(DAFTAR_FIXTURE!$B$2:$B$51,MATCH(T18,DAFTAR_FIXTURE!$A$2:$A$51,0)),"")) | AA18: =IF(T18="","",IF(Z18="","CEK ID FIXTURE tidak ada di DAFTAR_FIXTURE",IF(U18="","CEK ZONA NO kosong",IF(ISNA(MATCH(Z18&"|"&U18,LAYOUT!$E$2:$E$80,0)),"CEK ZONA NO di luar layout",IF(V18<>INDEX(LAYOUT!$D$2:$D$80,MATCH(Z18&"|"&U18,LAYOUT!$E$2:$E$80,0)),"CEK JENIS ZONA",IF($D18="","Zona STOCK",IF($E18="","CEK SKU DESCRIPTION kosong",IF(AND(W18<>"",X18=""),"CEK URUTAN SAMBUNG kosong",IF(AND(W18<>"",LEFT(Z18,6)="Endcap"),"CEK Endcap tidak ikut sambung","OK"))))))))) | AH18: =IF(AB18="","",IFERROR(INDEX(DAFTAR_FIXTURE!$B$2:$B$51,MATCH(AB18,DAFTAR_FIXTURE!$A$2:$A$51,0)),"")) | AI18: =IF(AB18="","",IF(AH18="","CEK ID FIXTURE tidak ada di DAFTAR_FIXTURE",IF(AC18="","CEK ZONA NO kosong",IF(ISNA(MATCH(AH18&"|"&AC18,LAYOUT!$E$2:$E$80,0)),"CEK ZONA NO di luar layout",IF(AD18<>INDEX(LAYOUT!$D$2:$D$80,MATCH(AH18&"|"&AC18,LAYOUT!$E$2:$E$80,0)),"CEK JENIS ZONA",IF($D18="","Zona STOCK",IF($E18="","CEK SKU DESCRIPTION kosong",IF(AND(AE18<>"",AF18=""),"CEK URUTAN SAMBUNG kosong",IF(AND(AE18<>"",LEFT(AH18,6)="Endcap"),"CEK Endcap tidak ikut sambung","OK")))))))))
... R500: =IF(L500="","",IFERROR(INDEX(DAFTAR_FIXTURE!$B$2:$B$51,MATCH(L500,DAFTAR_FIXTURE!$A$2:$A$51,0)),"")) | S500: =IF(AND($D500="",L500=""),"",IF(L500="",IF(AND(T500="",AB500=""),"Belum ditempatkan",""),IF(R500="","CEK ID FIXTURE tidak ada di DAFTAR_FIXTURE",IF(M500="","CEK ZONA NO kosong",IF(ISNA(MATCH(R500&"|"&M500,LAYOUT!$E$2:$E$80,0)),"CEK ZONA NO di luar layout",IF(N500<>INDEX(LAYOUT!$D$2:$D$80,MATCH(R500&"|"&M500,LAYOUT!$E$2:$E$80,0)),"CEK JENIS ZONA",IF($D500="","Zona STOCK",IF($E500="","CEK SKU DESCRIPTION kosong",IF(AND(O500<>"",P500=""),"CEK URUTAN SAMBUNG kosong",IF(AND(O500<>"",LEFT(R500,6)="Endcap"),"CEK Endcap tidak ikut sambung","OK")))))))))) | Z500: =IF(T500="","",IFERROR(INDEX(DAFTAR_FIXTURE!$B$2:$B$51,MATCH(T500,DAFTAR_FIXTURE!$A$2:$A$51,0)),"")) | AA500: =IF(T500="","",IF(Z500="","CEK ID FIXTURE tidak ada di DAFTAR_FIXTURE",IF(U500="","CEK ZONA NO kosong",IF(ISNA(MATCH(Z500&"|"&U500,LAYOUT!$E$2:$E$80,0)),"CEK ZONA NO di luar layout",IF(V500<>INDEX(LAYOUT!$D$2:$D$80,MATCH(Z500&"|"&U500,LAYOUT!$E$2:$E$80,0)),"CEK JENIS ZONA",IF($D500="","Zona STOCK",IF($E500="","CEK SKU DESCRIPTION kosong",IF(AND(W500<>"",X500=""),"CEK URUTAN SAMBUNG kosong",IF(AND(W500<>"",LEFT(Z500,6)="Endcap"),"CEK Endcap tidak ikut sambung","OK"))))))))) | AH500: =IF(AB500="","",IFERROR(INDEX(DAFTAR_FIXTURE!$B$2:$B$51,MATCH(AB500,DAFTAR_FIXTURE!$A$2:$A$51,0)),"")) | AI500: =IF(AB500="","",IF(AH500="","CEK ID FIXTURE tidak ada di DAFTAR_FIXTURE",IF(AC500="","CEK ZONA NO kosong",IF(ISNA(MATCH(AH500&"|"&AC500,LAYOUT!$E$2:$E$80,0)),"CEK ZONA NO di luar layout",IF(AD500<>INDEX(LAYOUT!$D$2:$D$80,MATCH(AH500&"|"&AC500,LAYOUT!$E$2:$E$80,0)),"CEK JENIS ZONA",IF($D500="","Zona STOCK",IF($E500="","CEK SKU DESCRIPTION kosong",IF(AND(AE500<>"",AF500=""),"CEK URUTAN SAMBUNG kosong",IF(AND(AE500<>"",LEFT(AH500,6)="Endcap"),"CEK Endcap tidak ikut sambung","OK")))))))))

Sheet DIMENSI
A1: SKU * | B1: SKU DESCRIPTION (otomatis dari DATA) | C1: LEBAR (cm) * | D1: TINGGI (cm) * | E1: KEDALAMAN (cm) * | F1: FACING (opsional) | G1: MAKS SUSUN (opsional) | H1: BOLEH DIPUTAR (opsional) | I1: CATATAN (opsional) | J1: ESTIMASI PCS / FACING (otomatis) | K1: STATUS (otomatis) | M1: PARAMETER ESTIMASI (boleh diubah) | N1: nilai
A2: 10681571 | B2: =IF(A2="","",IFERROR(INDEX(DATA!$E$2:$E$500,MATCH(A2,DATA!$D$2:$D$500,0)),"")) | C2: 26 | D2: 8 | E2: 26 | F2: 1 | G2: 4 | H2: Tidak | I2: contoh baris: hapus lalu isi dimensi SKU Anda | J2: =IF(OR(A2="",COUNT(C2:E2)<3),"",IFERROR(MAX(0,FLOOR(($N$2-$N$3)/E2,1))*MAX(1,MIN(IF(G2="",1,G2),FLOOR($N$4/D2,1)))*IF(F2="",1,F2),"")) | K2: =IF(A2="","",IF(COUNTIF(DATA!$D$2:$D$500,A2)=0,"CEK SKU tidak ada di DATA",IF(COUNT(C2:E2)<3,"CEK dimensi belum lengkap",IF(OR(C2<=0,D2<=0,E2<=0),"CEK dimensi harus lebih dari 0",IF(COUNTIF($A$2:$A$500,A2)>1,"CEK SKU dobel","OK"))))) | M2: Kedalaman rak (cm) | N2: 50
B3: =IF(A3="","",IFERROR(INDEX(DATA!$E$2:$E$500,MATCH(A3,DATA!$D$2:$D$500,0)),"")) | J3: =IF(OR(A3="",COUNT(C3:E3)<3),"",IFERROR(MAX(0,FLOOR(($N$2-$N$3)/E3,1))*MAX(1,MIN(IF(G3="",1,G3),FLOOR($N$4/D3,1)))*IF(F3="",1,F3),"")) | K3: =IF(A3="","",IF(COUNTIF(DATA!$D$2:$D$500,A3)=0,"CEK SKU tidak ada di DATA",IF(COUNT(C3:E3)<3,"CEK dimensi belum lengkap",IF(OR(C3<=0,D3<=0,E3<=0),"CEK dimensi harus lebih dari 0",IF(COUNTIF($A$2:$A$500,A3)>1,"CEK SKU dobel","OK"))))) | M3: Ruang bebas depan-belakang (cm) | N3: 2
B4: =IF(A4="","",IFERROR(INDEX(DATA!$E$2:$E$500,MATCH(A4,DATA!$D$2:$D$500,0)),"")) | J4: =IF(OR(A4="",COUNT(C4:E4)<3),"",IFERROR(MAX(0,FLOOR(($N$2-$N$3)/E4,1))*MAX(1,MIN(IF(G4="",1,G4),FLOOR($N$4/D4,1)))*IF(F4="",1,F4),"")) | K4: =IF(A4="","",IF(COUNTIF(DATA!$D$2:$D$500,A4)=0,"CEK SKU tidak ada di DATA",IF(COUNT(C4:E4)<3,"CEK dimensi belum lengkap",IF(OR(C4<=0,D4<=0,E4<=0),"CEK dimensi harus lebih dari 0",IF(COUNTIF($A$2:$A$500,A4)>1,"CEK SKU dobel","OK"))))) | M4: Tinggi ruang rak (cm) | N4: 35
B5: =IF(A5="","",IFERROR(INDEX(DATA!$E$2:$E$500,MATCH(A5,DATA!$D$2:$D$500,0)),"")) | J5: =IF(OR(A5="",COUNT(C5:E5)<3),"",IFERROR(MAX(0,FLOOR(($N$2-$N$3)/E5,1))*MAX(1,MIN(IF(G5="",1,G5),FLOOR($N$4/D5,1)))*IF(F5="",1,F5),"")) | K5: =IF(A5="","",IF(COUNTIF(DATA!$D$2:$D$500,A5)=0,"CEK SKU tidak ada di DATA",IF(COUNT(C5:E5)<3,"CEK dimensi belum lengkap",IF(OR(C5<=0,D5<=0,E5<=0),"CEK dimensi harus lebih dari 0",IF(COUNTIF($A$2:$A$500,A5)>1,"CEK SKU dobel","OK"))))) | M5: Panjang gantungan (cm) | N5: 25
B6: =IF(A6="","",IFERROR(INDEX(DATA!$E$2:$E$500,MATCH(A6,DATA!$D$2:$D$500,0)),"")) | J6: =IF(OR(A6="",COUNT(C6:E6)<3),"",IFERROR(MAX(0,FLOOR(($N$2-$N$3)/E6,1))*MAX(1,MIN(IF(G6="",1,G6),FLOOR($N$4/D6,1)))*IF(F6="",1,F6),"")) | K6: =IF(A6="","",IF(COUNTIF(DATA!$D$2:$D$500,A6)=0,"CEK SKU tidak ada di DATA",IF(COUNT(C6:E6)<3,"CEK dimensi belum lengkap",IF(OR(C6<=0,D6<=0,E6<=0),"CEK dimensi harus lebih dari 0",IF(COUNTIF($A$2:$A$500,A6)>1,"CEK SKU dobel","OK")))))
B7: =IF(A7="","",IFERROR(INDEX(DATA!$E$2:$E$500,MATCH(A7,DATA!$D$2:$D$500,0)),"")) | J7: =IF(OR(A7="",COUNT(C7:E7)<3),"",IFERROR(MAX(0,FLOOR(($N$2-$N$3)/E7,1))*MAX(1,MIN(IF(G7="",1,G7),FLOOR($N$4/D7,1)))*IF(F7="",1,F7),"")) | K7: =IF(A7="","",IF(COUNTIF(DATA!$D$2:$D$500,A7)=0,"CEK SKU tidak ada di DATA",IF(COUNT(C7:E7)<3,"CEK dimensi belum lengkap",IF(OR(C7<=0,D7<=0,E7<=0),"CEK dimensi harus lebih dari 0",IF(COUNTIF($A$2:$A$500,A7)>1,"CEK SKU dobel","OK"))))) | M7: Catatan: kolom ESTIMASI hanya gambaran cepat untuk RAK (kedalaman rak 50 cm); tidak berlaku untuk kemasan gantung. Aplikasi memakai ukuran fixture dan zona yang sebenarnya, dan memakai "Panjang gantungan" untuk zona Gantungan.
B8: =IF(A8="","",IFERROR(INDEX(DATA!$E$2:$E$500,MATCH(A8,DATA!$D$2:$D$500,0)),"")) | J8: =IF(OR(A8="",COUNT(C8:E8)<3),"",IFERROR(MAX(0,FLOOR(($N$2-$N$3)/E8,1))*MAX(1,MIN(IF(G8="",1,G8),FLOOR($N$4/D8,1)))*IF(F8="",1,F8),"")) | K8: =IF(A8="","",IF(COUNTIF(DATA!$D$2:$D$500,A8)=0,"CEK SKU tidak ada di DATA",IF(COUNT(C8:E8)<3,"CEK dimensi belum lengkap",IF(OR(C8<=0,D8<=0,E8<=0),"CEK dimensi harus lebih dari 0",IF(COUNTIF($A$2:$A$500,A8)>1,"CEK SKU dobel","OK")))))
B9: =IF(A9="","",IFERROR(INDEX(DATA!$E$2:$E$500,MATCH(A9,DATA!$D$2:$D$500,0)),"")) | J9: =IF(OR(A9="",COUNT(C9:E9)<3),"",IFERROR(MAX(0,FLOOR(($N$2-$N$3)/E9,1))*MAX(1,MIN(IF(G9="",1,G9),FLOOR($N$4/D9,1)))*IF(F9="",1,F9),"")) | K9: =IF(A9="","",IF(COUNTIF(DATA!$D$2:$D$500,A9)=0,"CEK SKU tidak ada di DATA",IF(COUNT(C9:E9)<3,"CEK dimensi belum lengkap",IF(OR(C9<=0,D9<=0,E9<=0),"CEK dimensi harus lebih dari 0",IF(COUNTIF($A$2:$A$500,A9)>1,"CEK SKU dobel","OK")))))
B10: =IF(A10="","",IFERROR(INDEX(DATA!$E$2:$E$500,MATCH(A10,DATA!$D$2:$D$500,0)),"")) | J10: =IF(OR(A10="",COUNT(C10:E10)<3),"",IFERROR(MAX(0,FLOOR(($N$2-$N$3)/E10,1))*MAX(1,MIN(IF(G10="",1,G10),FLOOR($N$4/D10,1)))*IF(F10="",1,F10),"")) | K10: =IF(A10="","",IF(COUNTIF(DATA!$D$2:$D$500,A10)=0,"CEK SKU tidak ada di DATA",IF(COUNT(C10:E10)<3,"CEK dimensi belum lengkap",IF(OR(C10<=0,D10<=0,E10<=0),"CEK dimensi harus lebih dari 0",IF(COUNTIF($A$2:$A$500,A10)>1,"CEK SKU dobel","OK")))))
B11: =IF(A11="","",IFERROR(INDEX(DATA!$E$2:$E$500,MATCH(A11,DATA!$D$2:$D$500,0)),"")) | J11: =IF(OR(A11="",COUNT(C11:E11)<3),"",IFERROR(MAX(0,FLOOR(($N$2-$N$3)/E11,1))*MAX(1,MIN(IF(G11="",1,G11),FLOOR($N$4/D11,1)))*IF(F11="",1,F11),"")) | K11: =IF(A11="","",IF(COUNTIF(DATA!$D$2:$D$500,A11)=0,"CEK SKU tidak ada di DATA",IF(COUNT(C11:E11)<3,"CEK dimensi belum lengkap",IF(OR(C11<=0,D11<=0,E11<=0),"CEK dimensi harus lebih dari 0",IF(COUNTIF($A$2:$A$500,A11)>1,"CEK SKU dobel","OK")))))
B12: =IF(A12="","",IFERROR(INDEX(DATA!$E$2:$E$500,MATCH(A12,DATA!$D$2:$D$500,0)),"")) | J12: =IF(OR(A12="",COUNT(C12:E12)<3),"",IFERROR(MAX(0,FLOOR(($N$2-$N$3)/E12,1))*MAX(1,MIN(IF(G12="",1,G12),FLOOR($N$4/D12,1)))*IF(F12="",1,F12),"")) | K12: =IF(A12="","",IF(COUNTIF(DATA!$D$2:$D$500,A12)=0,"CEK SKU tidak ada di DATA",IF(COUNT(C12:E12)<3,"CEK dimensi belum lengkap",IF(OR(C12<=0,D12<=0,E12<=0),"CEK dimensi harus lebih dari 0",IF(COUNTIF($A$2:$A$500,A12)>1,"CEK SKU dobel","OK")))))
B13: =IF(A13="","",IFERROR(INDEX(DATA!$E$2:$E$500,MATCH(A13,DATA!$D$2:$D$500,0)),"")) | J13: =IF(OR(A13="",COUNT(C13:E13)<3),"",IFERROR(MAX(0,FLOOR(($N$2-$N$3)/E13,1))*MAX(1,MIN(IF(G13="",1,G13),FLOOR($N$4/D13,1)))*IF(F13="",1,F13),"")) | K13: =IF(A13="","",IF(COUNTIF(DATA!$D$2:$D$500,A13)=0,"CEK SKU tidak ada di DATA",IF(COUNT(C13:E13)<3,"CEK dimensi belum lengkap",IF(OR(C13<=0,D13<=0,E13<=0),"CEK dimensi harus lebih dari 0",IF(COUNTIF($A$2:$A$500,A13)>1,"CEK SKU dobel","OK")))))
B14: =IF(A14="","",IFERROR(INDEX(DATA!$E$2:$E$500,MATCH(A14,DATA!$D$2:$D$500,0)),"")) | J14: =IF(OR(A14="",COUNT(C14:E14)<3),"",IFERROR(MAX(0,FLOOR(($N$2-$N$3)/E14,1))*MAX(1,MIN(IF(G14="",1,G14),FLOOR($N$4/D14,1)))*IF(F14="",1,F14),"")) | K14: =IF(A14="","",IF(COUNTIF(DATA!$D$2:$D$500,A14)=0,"CEK SKU tidak ada di DATA",IF(COUNT(C14:E14)<3,"CEK dimensi belum lengkap",IF(OR(C14<=0,D14<=0,E14<=0),"CEK dimensi harus lebih dari 0",IF(COUNTIF($A$2:$A$500,A14)>1,"CEK SKU dobel","OK")))))
B15: =IF(A15="","",IFERROR(INDEX(DATA!$E$2:$E$500,MATCH(A15,DATA!$D$2:$D$500,0)),"")) | J15: =IF(OR(A15="",COUNT(C15:E15)<3),"",IFERROR(MAX(0,FLOOR(($N$2-$N$3)/E15,1))*MAX(1,MIN(IF(G15="",1,G15),FLOOR($N$4/D15,1)))*IF(F15="",1,F15),"")) | K15: =IF(A15="","",IF(COUNTIF(DATA!$D$2:$D$500,A15)=0,"CEK SKU tidak ada di DATA",IF(COUNT(C15:E15)<3,"CEK dimensi belum lengkap",IF(OR(C15<=0,D15<=0,E15<=0),"CEK dimensi harus lebih dari 0",IF(COUNTIF($A$2:$A$500,A15)>1,"CEK SKU dobel","OK")))))
B16: =IF(A16="","",IFERROR(INDEX(DATA!$E$2:$E$500,MATCH(A16,DATA!$D$2:$D$500,0)),"")) | J16: =IF(OR(A16="",COUNT(C16:E16)<3),"",IFERROR(MAX(0,FLOOR(($N$2-$N$3)/E16,1))*MAX(1,MIN(IF(G16="",1,G16),FLOOR($N$4/D16,1)))*IF(F16="",1,F16),"")) | K16: =IF(A16="","",IF(COUNTIF(DATA!$D$2:$D$500,A16)=0,"CEK SKU tidak ada di DATA",IF(COUNT(C16:E16)<3,"CEK dimensi belum lengkap",IF(OR(C16<=0,D16<=0,E16<=0),"CEK dimensi harus lebih dari 0",IF(COUNTIF($A$2:$A$500,A16)>1,"CEK SKU dobel","OK")))))
B17: =IF(A17="","",IFERROR(INDEX(DATA!$E$2:$E$500,MATCH(A17,DATA!$D$2:$D$500,0)),"")) | J17: =IF(OR(A17="",COUNT(C17:E17)<3),"",IFERROR(MAX(0,FLOOR(($N$2-$N$3)/E17,1))*MAX(1,MIN(IF(G17="",1,G17),FLOOR($N$4/D17,1)))*IF(F17="",1,F17),"")) | K17: =IF(A17="","",IF(COUNTIF(DATA!$D$2:$D$500,A17)=0,"CEK SKU tidak ada di DATA",IF(COUNT(C17:E17)<3,"CEK dimensi belum lengkap",IF(OR(C17<=0,D17<=0,E17<=0),"CEK dimensi harus lebih dari 0",IF(COUNTIF($A$2:$A$500,A17)>1,"CEK SKU dobel","OK")))))
B18: =IF(A18="","",IFERROR(INDEX(DATA!$E$2:$E$500,MATCH(A18,DATA!$D$2:$D$500,0)),"")) | J18: =IF(OR(A18="",COUNT(C18:E18)<3),"",IFERROR(MAX(0,FLOOR(($N$2-$N$3)/E18,1))*MAX(1,MIN(IF(G18="",1,G18),FLOOR($N$4/D18,1)))*IF(F18="",1,F18),"")) | K18: =IF(A18="","",IF(COUNTIF(DATA!$D$2:$D$500,A18)=0,"CEK SKU tidak ada di DATA",IF(COUNT(C18:E18)<3,"CEK dimensi belum lengkap",IF(OR(C18<=0,D18<=0,E18<=0),"CEK dimensi harus lebih dari 0",IF(COUNTIF($A$2:$A$500,A18)>1,"CEK SKU dobel","OK")))))
B19: =IF(A19="","",IFERROR(INDEX(DATA!$E$2:$E$500,MATCH(A19,DATA!$D$2:$D$500,0)),"")) | J19: =IF(OR(A19="",COUNT(C19:E19)<3),"",IFERROR(MAX(0,FLOOR(($N$2-$N$3)/E19,1))*MAX(1,MIN(IF(G19="",1,G19),FLOOR($N$4/D19,1)))*IF(F19="",1,F19),"")) | K19: =IF(A19="","",IF(COUNTIF(DATA!$D$2:$D$500,A19)=0,"CEK SKU tidak ada di DATA",IF(COUNT(C19:E19)<3,"CEK dimensi belum lengkap",IF(OR(C19<=0,D19<=0,E19<=0),"CEK dimensi harus lebih dari 0",IF(COUNTIF($A$2:$A$500,A19)>1,"CEK SKU dobel","OK")))))
... B500: =IF(A500="","",IFERROR(INDEX(DATA!$E$2:$E$500,MATCH(A500,DATA!$D$2:$D$500,0)),"")) | J500: =IF(OR(A500="",COUNT(C500:E500)<3),"",IFERROR(MAX(0,FLOOR(($N$2-$N$3)/E500,1))*MAX(1,MIN(IF(G500="",1,G500),FLOOR($N$4/D500,1)))*IF(F500="",1,F500),"")) | K500: =IF(A500="","",IF(COUNTIF(DATA!$D$2:$D$500,A500)=0,"CEK SKU tidak ada di DATA",IF(COUNT(C500:E500)<3,"CEK dimensi belum lengkap",IF(OR(C500<=0,D500<=0,E500<=0),"CEK dimensi harus lebih dari 0",IF(COUNTIF($A$2:$A$500,A500)>1,"CEK SKU dobel","OK")))))

Sheet DAFTAR_FIXTURE
A1: id_fixture | B1: jenis_fixture | C1: keterangan (opsional: toko / lokasi) | E1: JENIS FIXTURE (referensi) | F1: UKURAN P×L×T (cm) | G1: JUMLAH ZONA | H1: SUSUNAN ZONA (atas → bawah) | I1: BISA DISAMBUNG
A2: WLL 3S + 2G | B2: Wall 3 Shelving + 2 Gantungan | E2: Wall 6 Shelving | F2: 120x50x270 / 120x50x240 | G2: 6 | H2: 1 Shelving · 2 Shelving · 3 Shelving · 4 Shelving · 5 Shelving · 6 Shelving | I2: Ya
A3: WLL 5S | B3: Wall 5 Shelving | E3: Wall 5 Shelving | F3: 120x50x270 / 120x50x240 | G3: 5 | H3: 1 Shelving · 2 Shelving · 3 Shelving · 4 Shelving · 5 Shelving | I3: Ya
A4: WLL 6S | B4: Wall 6 Shelving | E4: Wall 3 Shelving + 2 Gantungan | F4: 120x50x270 / 120x50x240 | G4: 5 | H4: 1 Gantungan · 2 Gantungan · 3 Shelving · 4 Shelving · 5 Shelving | I4: Ya
A5: GDN 2G + 2S | B5: Gondola 2 Gantungan + 2 Shelving | E5: Gondola 4 Shelving | F5: 120x50x150 | G5: 4 | H5: 1 Shelving · 2 Shelving · 3 Shelving · 4 Shelving | I5: Ya
A6: GDN 2S + 2G | B6: Gondola 2 Shelving + 2 Gantungan | E6: Gondola 3 Shelving | F6: 120x50x150 | G6: 3 | H6: 1 Shelving · 2 Shelving · 3 Shelving | I6: Ya
A7: GDN 3S | B7: Gondola 3 Shelving | E7: Gondola 2 Gantungan + 2 Shelving | F7: 120x50x150 | G7: 4 | H7: 1 Gantungan · 2 Gantungan · 3 Shelving · 4 Shelving | I7: Ya
A8: GDN 3S + 1G | B8: Gondola 3 Shelving + 1 Gantungan | E8: Gondola 3 Shelving + 1 Gantungan | F8: 120x50x150 | G8: 4 | H8: 1 Shelving · 2 Gantungan · 3 Shelving · 4 Shelving | I8: Ya
A9: GDN 4S | B9: Gondola 4 Shelving | E9: Gondola 2 Shelving + 2 Gantungan | F9: 120x50x150 | G9: 4 | H9: 1 Shelving · 2 Gantungan · 3 Gantungan · 4 Shelving | I9: Ya
A10: END 3S | B10: Endcap 3 Shelving | E10: Endcap 4 Shelving | F10: 100x50x150 | G10: 4 | H10: 1 Shelving · 2 Shelving · 3 Shelving · 4 Shelving | I10: Tidak
A11: END 4S | B11: Endcap 4 Shelving | E11: Endcap 3 Shelving | F11: 100x50x150 | G11: 3 | H11: 1 Shelving · 2 Shelving · 3 Shelving | I11: Tidak
A12: PLT 90 | B12: Pallet 90x90 | E12: Pallet 90x90 | F12: 90x90x100 | G12: 1 | H12: 1 Shelving | I12: Ya
E14: Cara pakai:
E15: • Kolom A–C = daftar fixture di toko Anda. Satu ID satu fixture, harus unik (maks. baris 51).
E16: • Kolom B dipilih dari dropdown. Nama persis sama dengan kolom E.
E17: • ID kolom A muncul sebagai dropdown di sheet DATA (ID FIXTURE 1, 2, 3). Pakai kode modul: GDN 3S = Gondola 3 Shelving, 2G = 2 Gantungan. Fixture ke-2 jenis sama: tambah " #2".
E18: • Kolom E–I hanya referensi (jangan diubah). Zona dihitung dari atas ke bawah.

Sheet LAYOUT
A1: jenis_fixture | B1: ukuran_LxDxT_cm | C1: zona_no | D1: jenis_zona_seharusnya | E1: kunci
A2: Wall 6 Shelving | B2: 120x50x270 / 120x50x240 | C2: 1 | D2: Shelving | E2: =A2&"|"&C2
A3: Wall 6 Shelving | B3: 120x50x270 / 120x50x240 | C3: 2 | D3: Shelving | E3: =A3&"|"&C3
A4: Wall 6 Shelving | B4: 120x50x270 / 120x50x240 | C4: 3 | D4: Shelving | E4: =A4&"|"&C4
A5: Wall 6 Shelving | B5: 120x50x270 / 120x50x240 | C5: 4 | D5: Shelving | E5: =A5&"|"&C5
A6: Wall 6 Shelving | B6: 120x50x270 / 120x50x240 | C6: 5 | D6: Shelving | E6: =A6&"|"&C6
A7: Wall 6 Shelving | B7: 120x50x270 / 120x50x240 | C7: 6 | D7: Shelving | E7: =A7&"|"&C7
A8: Wall 5 Shelving | B8: 120x50x270 / 120x50x240 | C8: 1 | D8: Shelving | E8: =A8&"|"&C8
A9: Wall 5 Shelving | B9: 120x50x270 / 120x50x240 | C9: 2 | D9: Shelving | E9: =A9&"|"&C9
A10: Wall 5 Shelving | B10: 120x50x270 / 120x50x240 | C10: 3 | D10: Shelving | E10: =A10&"|"&C10
A11: Wall 5 Shelving | B11: 120x50x270 / 120x50x240 | C11: 4 | D11: Shelving | E11: =A11&"|"&C11
A12: Wall 5 Shelving | B12: 120x50x270 / 120x50x240 | C12: 5 | D12: Shelving | E12: =A12&"|"&C12
A13: Wall 3 Shelving + 2 Gantungan | B13: 120x50x270 / 120x50x240 | C13: 1 | D13: Gantungan | E13: =A13&"|"&C13
... A44: Pallet 90x90 | B44: 90x90x100 | C44: 1 | D44: Shelving | E44: =A44&"|"&C44
A46: Sheet ini referensi (jangan diubah). Zona dihitung dari atas ke bawah.
